Workbook
Name SegmentaciónDeDatos_Mes_Año: #N/A

Sheet Ordenes
A1: Mes | B1: Fecha_Conta | C1: BELNR_ID | D1: ItemCode | E1: Descripción | F1: Sec | G1: Fecha Inicio | H1: Cantidad Base | I1: Horas | J1: Maquina | K1: Planificado | L1: Proceso | M1: Horas Programadas | N1: Línea | O1: Subcomponente | P1: Estado | Q1: Avance_SAP | R1: Fecha_Gantt_Desde
A2: =+MONTH(Ordenes_Mes[[#This Row],[Fecha_Conta]]) -> 4 | B2: =+VLOOKUP(C2,OP!$A$1:$P$27848,12,FALSE) -> 46113 | C2: 3955 | D2: 2140150001 | E2: Archivador Plastificado Negro, Lomo Ancho, t/Oficio Layconsa Office | F2: =+_xlfn.XLOOKUP(D2,BD_Spec!$A$1:$A$2336,BD_Spec!$L$1:$L$2336) -> 1 | G2: 46113 | H2: =+VLOOKUP(D2,Tiempos!$A$1:$N$7440,3,FALSE) -> 3500 | I2: =+VLOOKUP(D2,Tiempos!$A$1:$N$7440,5,FALSE) -> 12 | J2: =+VLOOKUP(D2,Tiempos!$A$1:$N$7440,7,FALSE) -> AMAN02 | K2: =IF(VLOOKUP(C2,OP!$A$1:$P$27848,4,FALSE)="Cerrado",VLOOKUP(C2,OP!$A$1:$P$27848,10,FALSE),VLOOKUP(C2,OP!$A$1:$P$27848,9,FALSE)) -> 32441 | L2: =IF( IFERROR(VLOOKUP(D2,BD_Spec!$A$1:$D$2300,4,FALSE),"")="Producto Terminado", "TERMINADO", IFERROR(_xlfn.XLOOKUP(Ordenes_Mes[[#This Row],[Maquina]],Tiempos!$G$1:$G$766,Tiempos!$O$1:$O$766),"") ) -> TERMINADO | M2: =IF(OR(Ordenes_Mes[[#This Row],[Proceso]]="Plástico_lima",Ordenes_Mes[[#This Row],[Proceso]]="soplado"),24,12) -> 12 | N2: =+VLOOKUP(D2,BD_Spec!$A$1:$K$2336,7,FALSE) -> Manuales | O2: =+VLOOKUP(D2,BD_Spec!$A$1:$K$2336,8,FALSE) -> Archivador | P2: =+VLOOKUP(C2,OP!$A$1:$P$27848,4,FALSE) -> CERRADO | Q2: =+VLOOKUP(C2,OP!$A$1:$P$27848,10,FALSE) -> 32441 | R2: =+Ordenes_Mes[[#This Row],[Fecha Inicio]] -> 46113
A3: =+MONTH(Ordenes_Mes[[#This Row],[Fecha_Conta]]) -> 4 | B3: =+VLOOKUP(C3,OP!$A$1:$P$27848,12,FALSE) -> 46129 | C3: 4028 | D3: 2140250020 | E3: Papelógrafo Rayado Rllx3 57x83cm 56gr. 25mm | F3: 1 | G3: 46132 | H3: =+VLOOKUP(D3,Tiempos!$A$1:$N$7440,3,FALSE) -> 800 | I3: 12 | J3: =+VLOOKUP(D3,Tiempos!$A$1:$N$7440,7,FALSE) -> AMAN02 | K3: =IF(VLOOKUP(C3,OP!$A$1:$P$27848,4,FALSE)="Cerrado",VLOOKUP(C3,OP!$A$1:$P$27848,10,FALSE),VLOOKUP(C3,OP!$A$1:$P$27848,9,FALSE)) -> 5668 | L3: =IF( IFERROR(VLOOKUP(D3,BD_Spec!$A$1:$D$2300,4,FALSE),"")="Producto Terminado", "TERMINADO", IFERROR(_xlfn.XLOOKUP(Ordenes_Mes[[#This Row],[Maquina]],Tiempos!$G$1:$G$766,Tiempos!$O$1:$O$766),"") ) -> TERMINADO | M3: =IF(OR(Ordenes_Mes[[#This Row],[Proceso]]="Plástico_lima",Ordenes_Mes[[#This Row],[Proceso]]="soplado"),24,12) -> 12 | N3: =+VLOOKUP(D3,BD_Spec!$A$1:$K$2336,7,FALSE) -> Manuales | O3: =+VLOOKUP(D3,BD_Spec!$A$1:$K$2336,8,FALSE) -> Papelería | P3: =+VLOOKUP(C3,OP!$A$1:$P$27848,4,FALSE) -> CERRADO | Q3: =+VLOOKUP(C3,OP!$A$1:$P$27848,10,FALSE) -> 5668 | R3: =+Ordenes_Mes[[#This Row],[Fecha Inicio]] -> 46132
A4: =+MONTH(Ordenes_Mes[[#This Row],[Fecha_Conta]]) -> 4 | B4: =+VLOOKUP(C4,OP!$A$1:$P$27848,12,FALSE) -> 46125 | C4: 4003 | D4: 2310230105 | E4: Frasco Etiquetado Para Témpera 30 cc ARTI P.S. | F4: 1 | G4: 46127 | H4: =+VLOOKUP(D4,Tiempos!$A$1:$N$7440,3,FALSE) -> 25000 | I4: =+VLOOKUP(D4,Tiempos!$A$1:$N$7440,5,FALSE) -> 12 | J4: =+VLOOKUP(D4,Tiempos!$A$1:$N$7440,7,FALSE) -> AMAN02 | K4: =IF(VLOOKUP(C4,OP!$A$1:$P$27848,4,FALSE)="Cerrado",VLOOKUP(C4,OP!$A$1:$P$27848,10,FALSE),VLOOKUP(C4,OP!$A$1:$P$27848,9,FALSE)) -> 223775 | L4: =IF( IFERROR(VLOOKUP(D4,BD_Spec!$A$1:$D$2300,4,FALSE),"")="Producto Terminado", "TERMINADO", IFERROR(_xlfn.XLOOKUP(Ordenes_Mes[[#This Row],[Maquina]],Tiempos!$G$1:$G$766,Tiempos!$O$1:$O$766),"") ) -> ENSAMBLE_LIMA | M4: =IF(OR(Ordenes_Mes[[#This Row],[Proceso]]="Plástico_lima",Ordenes_Mes[[#This Row],[Proceso]]="soplado"),24,12) -> 12 | N4: =+VLOOKUP(D4,BD_Spec!$A$1:$K$2336,7,FALSE) -> Línea_30cc | O4: =+VLOOKUP(D4,BD_Spec!$A$1:$K$2336,8,FALSE) -> Frasco | P4: =+VLOOKUP(C4,OP!$A$1:$P$27848,4,FALSE) -> CERRADO | Q4: =+VLOOKUP(C4,OP!$A$1:$P$27848,10,FALSE) -> 223775 | R4: =+Ordenes_Mes[[#This Row],[Fecha Inicio]] -> 46127
A5: =+MONTH(Ordenes_Mes[[#This Row],[Fecha_Conta]]) -> 4 | B5: =+VLOOKUP(C5,OP!$A$1:$P$27848,12,FALSE) -> 46133 | C5: 4034 | D5: 2140370001 | E5: Papel Crepé Rojo Pqtx1 Layconsa | F5: 2 | G5: 46135 | H5: =+VLOOKUP(D5,Tiempos!$A$1:$N$7440,3,FALSE) -> 800 | I5: 12 | J5: =+VLOOKUP(D5,Tiempos!$A$1:$N$7440,7,FALSE) -> AMAN02 | K5: =IF(VLOOKUP(C5,OP!$A$1:$P$27848,4,FALSE)="Cerrado",VLOOKUP(C5,OP!$A$1:$P$27848,10,FALSE),VLOOKUP(C5,OP!$A$1:$P$27848,9,FALSE)) -> 2895 | L5: =IF( IFERROR(VLOOKUP(D5,BD_Spec!$A$1:$D$2300,4,FALSE),"")="Producto Terminado", "TERMINADO", IFERROR(_xlfn.XLOOKUP(Ordenes_Mes[[#This Row],[Maquina]],Tiempos!$G$1:$G$766,Tiempos!$O$1:$O$766),"") ) -> TERMINADO | M5: =IF(OR(Ordenes_Mes[[#This Row],[Proceso]]="Plástico_lima",Ordenes_Mes[[#This Row],[Proceso]]="soplado"),24,12) -> 12 | N5: =+VLOOKUP(D5,BD_Spec!$A$1:$K$2336,7,FALSE) -> Manuales | O5: =+VLOOKUP(D5,BD_Spec!$A$1:$K$2336,8,FALSE) -> Papelería | P5: =+VLOOKUP(C5,OP!$A$1:$P$27848,4,FALSE) -> CERRADO | Q5: =+VLOOKUP(C5,OP!$A$1:$P$27848,10,FALSE) -> 2895 | R5: =+Ordenes_Mes[[#This Row],[Fecha Inicio]] -> 46135
A6: =+MONTH(Ordenes_Mes[[#This Row],[Fecha_Conta]]) -> 4 | B6: =+VLOOKUP(C6,OP!$A$1:$P$27848,12,FALSE) -> 46135 | C6: 4041 | D6: 2140150001 | E6: Archivador Plastificado Negro, Lomo Ancho, t/Oficio Layconsa Office | F6: 2 | G6: 46136 | H6: =+VLOOKUP(D6,Tiempos!$A$1:$N$7440,3,FALSE) -> 3500 | I6: =+VLOOKUP(D6,Tiempos!$A$1:$N$7440,5,FALSE) -> 12 | J6: =+VLOOKUP(D6,Tiempos!$A$1:$N$7440,7,FALSE) -> AMAN02 | K6: =IF(VLOOKUP(C6,OP!$A$1:$P$27848,4,FALSE)="Cerrado",VLOOKUP(C6,OP!$A$1:$P$27848,10,FALSE),VLOOKUP(C6,OP!$A$1:$P$27848,9,FALSE)) -> 4944 | L6: =IF( IFERROR(VLOOKUP(D6,BD_Spec!$A$1:$D$2300,4,FALSE),"")="Producto Terminado", "TERMINADO", IFERROR(_xlfn.XLOOKUP(Ordenes_Mes[[#This Row],[Maquina]],Tiempos!$G$1:$G$766,Tiempos!$O$1:$O$766),"") ) -> TERMINADO | M6: =IF(OR(Ordenes_Mes[[#This Row],[Proceso]]="Plástico_lima",Ordenes_Mes[[#This Row],[Proceso]]="soplado"),24,12) -> 12 | N6: =+VLOOKUP(D6,BD_Spec!$A$1:$K$2336,7,FALSE) -> Manuales | O6: =+VLOOKUP(D6,BD_Spec!$A$1:$K$2336,8,FALSE) -> Archivador | P6: =+VLOOKUP(C6,OP!$A$1:$P$27848,4,FALSE) -> CERRADO | Q6: =+VLOOKUP(C6,OP!$A$1:$P$27848,10,FALSE) -> 4944 | R6: =+Ordenes_Mes[[#This Row],[Fecha Inicio]] -> 46136
A7: =+MONTH(Ordenes_Mes[[#This Row],[Fecha_Conta]]) -> 4 | B7: =+VLOOKUP(C7,OP!$A$1:$P$27848,12,FALSE) -> 46133 | C7: 4035 | D7: 2140370002 | E7: Papel Crepé Blanco Pqtx1 Layconsa | F7: 3 | G7: 46135 | H7: =+VLOOKUP(D7,Tiempos!$A$1:$N$7440,3,FALSE) -> 800 | I7: 12 | J7: =+VLOOKUP(D7,Tiempos!$A$1:$N$7440,7,FALSE) -> AMAN02 | K7: =IF(VLOOKUP(C7,OP!$A$1:$P$27848,4,FALSE)="Cerrado",VLOOKUP(C7,OP!$A$1:$P$27848,10,FALSE),VLOOKUP(C7,OP!$A$1:$P$27848,9,FALSE)) -> 1901 | L7: =IF( IFERROR(VLOOKUP(D7,BD_Spec!$A$1:$D$2300,4,FALSE),"")="Producto Terminado", "TERMINADO", IFERROR(_xlfn.XLOOKUP(Ordenes_Mes[[#This Row],[Maquina]],Tiempos!$G$1:$G$766,Tiempos!$O$1:$O$766),"") ) -> TERMINADO | M7: =IF(OR(Ordenes_Mes[[#This Row],[Proceso]]="Plástico_lima",Ordenes_Mes[[#This Row],[Proceso]]="soplado"),24,12) -> 12 | N7: =+VLOOKUP(D7,BD_Spec!$A$1:$K$2336,7,FALSE) -> Manuales | O7: =+VLOOKUP(D7,BD_Spec!$A$1:$K$2336,8,FALSE) -> Papelería | P7: =+VLOOKUP(C7,OP!$A$1:$P$27848,4,FALSE) -> CERRADO | Q7: =+VLOOKUP(C7,OP!$A$1:$P$27848,10,FALSE) -> 1901 | R7: =+Ordenes_Mes[[#This Row],[Fecha Inicio]] -> 46135
A8: =+MONTH(Ordenes_Mes[[#This Row],[Fecha_Conta]]) -> 4 | B8: =+VLOOKUP(C8,OP!$A$1:$P$27848,12,FALSE) -> 46133 | C8: 4036 | D8: 2140370011 | E8: Papel Crepé Verde Claro Pqtx1 Layconsa | F8: 4 | G8: 46134 | H8: =+VLOOKUP(D8,Tiempos!$A$1:$N$7440,3,FALSE) -> 800 | I8: 12 | J8: =+VLOOKUP(D8,Tiempos!$A$1:$N$7440,7,FALSE) -> AMAN02 | K8: =IF(VLOOKUP(C8,OP!$A$1:$P$27848,4,FALSE)="Cerrado",VLOOKUP(C8,OP!$A$1:$P$27848,10,FALSE),VLOOKUP(C8,OP!$A$1:$P$27848,9,FALSE)) -> 3051 | L8: =IF( IFERROR(VLOOKUP(D8,BD_Spec!$A$1:$D$2300,4,FALSE),"")="Producto Terminado", "TERMINADO", IFERROR(_xlfn.XLOOKUP(Ordenes_Mes[[#This Row],[Maquina]],Tiempos!$G$1:$G$766,Tiempos!$O$1:$O$766),"") ) -> TERMINADO | M8: =IF(OR(Ordenes_Mes[[#This Row],[Proceso]]="Plástico_lima",Ordenes_Mes[[#This Row],[Proceso]]="soplado"),24,12) -> 12 | N8: =+VLOOKUP(D8,BD_Spec!$A$1:$K$2336,7,FALSE) -> Manuales | O8: =+VLOOKUP(D8,BD_Spec!$A$1:$K$2336,8,FALSE) -> Papelería | P8: =+VLOOKUP(C8,OP!$A$1:$P$27848,4,FALSE) -> CERRADO | Q8: =+VLOOKUP(C8,OP!$A$1:$P$27848,10,FALSE) -> 3051 | R8: =+Ordenes_Mes[[#This Row],[Fecha Inicio]] -> 46134
A9: =+MONTH(Ordenes_Mes[[#This Row],[Fecha_Conta]]) -> 4 | B9: =+VLOOKUP(C9,OP!$A$1:$P$27848,12,FALSE) -> 46125 | C9: 4006 | D9: 2310320328 | E9: Carga Para Bolígrafo 036 PFTR Azul N | F9: 1 | G9: 46127 | H9: =+VLOOKUP(D9,Tiempos!$A$1:$N$7440,3,FALSE) -> 35000 | I9: =+VLOOKUP(D9,Tiempos!$A$1:$N$7440,5,FALSE) -> 12 | J9: =+VLOOKUP(D9,Tiempos!$A$1:$N$7440,7,FALSE) -> CAR02 | K9: =IF(VLOOKUP(C9,OP!$A$1:$P$27848,4,FALSE)="Cerrado",VLOOKUP(C9,OP!$A$1:$P$27848,10,FALSE),VLOOKUP(C9,OP!$A$1:$P$27848,9,FALSE)) -> 220032 | L9: =IF( IFERROR(VLOOKUP(D9,BD_Spec!$A$1:$D$2300,4,FALSE),"")="Producto Terminado", "TERMINADO", IFERROR(_xlfn.XLOOKUP(Ordenes_Mes[[#This Row],[Maquina]],Tiempos!$G$1:$G$766,Tiempos!$O$1:$O$766),"") ) -> ENSAMBLE_LIMA | M9: =IF(OR(Ordenes_Mes[[#This Row],[Proceso]]="Plástico_lima",Ordenes_Mes[[#This Row],[Proceso]]="soplado"),24,12) -> 12 | N9: =+VLOOKUP(D9,BD_Spec!$A$1:$K$2336,7,FALSE) -> Línea_036 | O9: =+VLOOKUP(D9,BD_Spec!$A$1:$K$2336,8,FALSE) -> Colores | P9: =+VLOOKUP(C9,OP!$A$1:$P$27848,4,FALSE) -> CERRADO | Q9: =+VLOOKUP(C9,OP!$A$1:$P$27848,10,FALSE) -> 220032 | R9: =+Ordenes_Mes[[#This Row],[Fecha Inicio]] -> 46127
A10: =+MONTH(Ordenes_Mes[[#This Row],[Fecha_Conta]]) -> 4 | B10: =+VLOOKUP(C10,OP!$A$1:$P$27848,12,FALSE) -> 46113 | C10: 4007 | D10: 2310320329 | E10: Carga Para Bolígrafo 036 PFTR Rojo N | F10: 2 | G10: 46132 | H10: =+VLOOKUP(D10,Tiempos!$A$1:$N$7440,3,FALSE) -> 35000 | I10: =+VLOOKUP(D10,Tiempos!$A$1:$N$7440,5,FALSE) -> 12 | J10: =+VLOOKUP(D10,Tiempos!$A$1:$N$7440,7,FALSE) -> CAR02 | K10: =IF(VLOOKUP(C10,OP!$A$1:$P$27848,4,FALSE)="Cerrado",VLOOKUP(C10,OP!$A$1:$P$27848,10,FALSE),VLOOKUP(C10,OP!$A$1:$P$27848,9,FALSE)) -> 61920 | L10: =IF( IFERROR(VLOOKUP(D10,BD_Spec!$A$1:$D$2300,4,FALSE),"")="Producto Terminado", "TERMINADO", IFERROR(_xlfn.XLOOKUP(Ordenes_Mes[[#This Row],[Maquina]],Tiempos!$G$1:$G$766,Tiempos!$O$1:$O$766),"") ) -> ENSAMBLE_LIMA | M10: =IF(OR(Ordenes_Mes[[#This Row],[Proceso]]="Plástico_lima",Ordenes_Mes[[#This Row],[Proceso]]="soplado"),24,12) -> 12 | N10: =+VLOOKUP(D10,BD_Spec!$A$1:$K$2336,7,FALSE) -> Línea_036 | O10: =+VLOOKUP(D10,BD_Spec!$A$1:$K$2336,8,FALSE) -> Colores | P10: =+VLOOKUP(C10,OP!$A$1:$P$27848,4,FALSE) -> CERRADO | Q10: =+VLOOKUP(C10,OP!$A$1:$P$27848,10,FALSE) -> 61920 | R10: =+Ordenes_Mes[[#This Row],[Fecha Inicio]] -> 46132
A11: =+MONTH(Ordenes_Mes[[#This Row],[Fecha_Conta]]) -> 4 | B11: =+VLOOKUP(C11,OP!$A$1:$P$27848,12,FALSE) -> 46132 | C11: 3989 | D11: 2110030170 | E11: Témperas Set x 7 x 30cc ARTI | F11: 1 | G11: 46132 | H11: =+VLOOKUP(D11,Tiempos!$A$1:$N$7440,3,FALSE) -> 6000 | I11: =+VLOOKUP(D11,Tiempos!$A$1:$N$7440,5,FALSE) -> 12 | J11: =+VLOOKUP(D11,Tiempos!$A$1:$N$7440,7,FALSE) -> DOSI_TEMP01 | K11: =IF(VLOOKUP(C11,OP!$A$1:$P$27848,4,FALSE)="Cerrado",VLOOKUP(C11,OP!$A$1:$P$27848,10,FALSE),VLOOKUP(C11,OP!$A$1:$P$27848,9,FALSE)) -> 25920 | L11: =IF( IFERROR(VLOOKUP(D11,BD_Spec!$A$1:$D$2300,4,FALSE),"")="Producto Terminado", "TERMINADO", IFERROR(_xlfn.XLOOKUP(Ordenes_Mes[[#This Row],[Maquina]],Tiempos!$G$1:$G$766,Tiempos!$O$1:$O$766),"") ) -> TERMINADO | M11: =IF(OR(Ordenes_Mes[[#This Row],[Proceso]]="Plástico_lima",Ordenes_Mes[[#This Row],[Proceso]]="soplado"),24,12) -> 12 | N11: =+VLOOKUP(D11,BD_Spec!$A$1:$K$2336,7,FALSE) -> Línea_30cc | O11: =+VLOOKUP(D11,BD_Spec!$A$1:$K$2336,8,FALSE) -> Témpera | P11: =+VLOOKUP(C11,OP!$A$1:$P$27848,4,FALSE) -> CERRADO | Q11: =+VLOOKUP(C11,OP!$A$1:$P$27848,10,FALSE) -> 25920 | R11: =+Ordenes_Mes[[#This Row],[Fecha Inicio]] -> 46132
A12: =+MONTH(Ordenes_Mes[[#This Row],[Fecha_Conta]]) -> 4 | B12: =+VLOOKUP(C12,OP!$A$1:$P$27848,12,FALSE) -> 46121 | C12: 3983 | D12: 2110040047 | E12: Crayón triangular cj. cartón Layconsa Puppy Jumbo x 12 | F12: 1 | G12: 46121 | H12: =+VLOOKUP(D12,Tiempos!$A$1:$N$7440,3,FALSE) -> 4000 | I12: 12 | J12: =+VLOOKUP(D12,Tiempos!$A$1:$N$7440,7,FALSE) -> ENCJ03 | K12: =IF(VLOOKUP(C12,OP!$A$1:$P$27848,4,FALSE)="Cerrado",VLOOKUP(C12,OP!$A$1:$P$27848,10,FALSE),VLOOKUP(C12,OP!$A$1:$P$27848,9,FALSE)) -> 3680 | L12: =IF( IFERROR(VLOOKUP(D12,BD_Spec!$A$1:$D$2300,4,FALSE),"")="Producto Terminado", "TERMINADO", IFERROR(_xlfn.XLOOKUP(Ordenes_Mes[[#This Row],[Maquina]],Tiempos!$G$1:$G$766,Tiempos!$O$1:$O$766),"") ) -> TERMINADO | M12: =IF(OR(Ordenes_Mes[[#This Row],[Proceso]]="Plástico_lima",Ordenes_Mes[[#This Row],[Proceso]]="soplado"),24,12) -> 12 | N12: =+VLOOKUP(D12,BD_Spec!$A$1:$K$2336,7,FALSE) -> Línea_Crayón | O12: =+VLOOKUP(D12,BD_Spec!$A$1:$K$2336,8,FALSE) -> Crayones | P12: =+VLOOKUP(C12,OP!$A$1:$P$27848,4,FALSE) -> CERRADO | Q12: =+VLOOKUP(C12,OP!$A$1:$P$27848,10,FALSE) -> 3680 | R12: =+Ordenes_Mes[[#This Row],[Fecha Inicio]] -> 46121
A13: =+MONTH(Ordenes_Mes[[#This Row],[Fecha_Conta]]) -> 4 | B13: =+VLOOKUP(C13,OP!$A$1:$P$27848,12,FALSE) -> 46119 | C13: 3980 | D13: 2310210138 | E13: Plumones LYC School 45 Granel Piel NP P.S. | F13: 1 | G13: 46119 | H13: =+VLOOKUP(D13,Tiempos!$A$1:$N$7440,3,FALSE) -> 50000 | I13: =+VLOOKUP(D13,Tiempos!$A$1:$N$7440,5,FALSE) -> 12 | J13: =+VLOOKUP(D13,Tiempos!$A$1:$N$7440,7,FALSE) -> ENS02 | K13: =IF(VLOOKUP(C13,OP!$A$1:$P$27848,4,FALSE)="Cerrado",VLOOKUP(C13,OP!$A$1:$P$27848,10,FALSE),VLOOKUP(C13,OP!$A$1:$P$27848,9,FALSE)) -> 11450 | L13: =IF( IFERROR(VLOOKUP(D13,BD_Spec!$A$1:$D$2300,4,FALSE),"")="Producto Terminado", "TERMINADO", IFERROR(_xlfn.XLOOKUP(Ordenes_Mes[[#This Row],[Maquina]],Tiempos!$G$1:$G$766,Tiempos!$O$1:$O$766),"") ) -> ENSAMBLE_LIMA | M13: =IF(OR(Ordenes_Mes[[#This Row],[Proceso]]="Plástico_lima",Ordenes_Mes[[#This Row],[Proceso]]="soplado"),24,12) -> 12 | N13: =+VLOOKUP(D13,BD_Spec!$A$1:$K$2336,7,FALSE) -> Línea_045 | O13: =+VLOOKUP(D13,BD_Spec!$A$1:$K$2336,8,FALSE) -> Ensamble_12 | P13: =+VLOOKUP(C13,OP!$A$1:$P$27848,4,FALSE) -> CERRADO | Q13: =+VLOOKUP(C13,OP!$A$1:$P$27848,10,FALSE) -> 11450 | R13: =+Ordenes_Mes[[#This Row],[Fecha Inicio]] -> 46119
A14: =+MONTH(Ordenes_Mes[[#This Row],[Fecha_Conta]]) -> 4 | B14: =+VLOOKUP(C14,OP!$A$1:$P$27848,12,FALSE) -> 46135 | C14: 4042 | D14: 2310210133 | E14: Plumones LYC School 45 Granel Anaranjado NP P.S. | F14: 2 | G14: 46136 | H14: =+VLOOKUP(D14,Tiempos!$A$1:$N$7440,3,FALSE) -> 50000 | I14: =+VLOOKUP(D14,Tiempos!$A$1:$N$7440,5,FALSE) -> 12 | J14: =+VLOOKUP(D14,Tiempos!$A$1:$N$7440,7,FALSE) -> ENS02 | K14: =IF(VLOOKUP(C14,OP!$A$1:$P$27848,4,FALSE)="Cerrado",VLOOKUP(C14,OP!$A$1:$P$27848,10,FALSE),VLOOKUP(C14,OP!$A$1:$P$27848,9,FALSE)) -> 50000 | L14: =IF( IFERROR(VLOOKUP(D14,BD_Spec!$A$1:$D$2300,4,FALSE),"")="Producto Terminado", "TERMINADO", IFERROR(_xlfn.XLOOKUP(Ordenes_Mes[[#This Row],[Maquina]],Tiempos!$G$1:$G$766,Tiempos!$O$1:$O$766),"") ) -> ENSAMBLE_LIMA | M14: =IF(OR(Ordenes_Mes[[#This Row],[Proceso]]="Plástico_lima",Ordenes_Mes[[#This Row],[Proceso]]="soplado"),24,12) -> 12 | N14: =+VLOOKUP(D14,BD_Spec!$A$1:$K$2336,7,FALSE) -> Línea_045 | O14: =+VLOOKUP(D14,BD_Spec!$A$1:$K$2336,8,FALSE) -> Ensamble_12 | P14: =+VLOOKUP(C14,OP!$A$1:$P$27848,4,FALSE) -> CERRADO | Q14: =+VLOOKUP(C14,OP!$A$1:$P$27848,10,FALSE) -> 50000 | R14: =+Ordenes_Mes[[#This Row],[Fecha Inicio]] -> 46136
A15: =+MONTH(Ordenes_Mes[[#This Row],[Fecha_Conta]]) -> 4 | B15: =+VLOOKUP(C15,OP!$A$1:$P$27848,12,FALSE) -> 46113 | C15: 3940 | D15: 2110080227 | E15: Bolígrafo Layconsa crystal L-036 Azul | F15: =+_xlfn.XLOOKUP(D15,BD_Spec!$A$1:$A$2336,BD_Spec!$L$1:$L$2336) -> 1 | G15: 46113 | H15: =+VLOOKUP(D15,Tiempos!$A$1:$N$7440,3,FALSE) -> 35000 | I15: =+VLOOKUP(D15,Tiempos!$A$1:$N$7440,5,FALSE) -> 12 | J15: =+VLOOKUP(D15,Tiempos!$A$1:$N$7440,7,FALSE) -> ENS03 | K15: =IF(VLOOKUP(C15,OP!$A$1:$P$27848,4,FALSE)="Cerrado",VLOOKUP(C15,OP!$A$1:$P$27848,10,FALSE),VLOOKUP(C15,OP!$A$1:$P$27848,9,FALSE)) -> 35000 | L15: =IF( IFERROR(VLOOKUP(D15,BD_Spec!$A$1:$D$2300,4,FALSE),"")="Producto Terminado", "TERMINADO", IFERROR(_xlfn.XLOOKUP(Ordenes_Mes[[#This Row],[Maquina]],Tiempos!$G$1:$G$766,Tiempos!$O$1:$O$766),"") ) -> TERMINADO | M15: =IF(OR(Ordenes_Mes[[#This Row],[Proceso]]="Plástico_lima",Ordenes_Mes[[#This Row],[Proceso]]="soplado"),24,12) -> 12 | N15: =+VLOOKUP(D15,BD_Spec!$A$1:$K$2336,7,FALSE) -> Línea_036 | O15: =+VLOOKUP(D15,BD_Spec!$A$1:$K$2336,8,FALSE) -> N/A | P15: =+VLOOKUP(C15,OP!$A$1:$P$27848,4,FALSE) -> CERRADO | Q15: =+VLOOKUP(C15,OP!$A$1:$P$27848,10,FALSE) -> 35000 | R15: =+Ordenes_Mes[[#This Row],[Fecha Inicio]] -> 46113
A16: =+MONTH(Ordenes_Mes[[#This Row],[Fecha_Conta]]) -> 4 | B16: =+VLOOKUP(C16,OP!$A$1:$P$27848,12,FALSE) -> 46139 | C16: 4097 | D16: 2110080228 | E16: Bolígrafo Layconsa crystal L-036 Negro | F16: 1 | G16: 46139 | H16: =+VLOOKUP(D16,Tiempos!$A$1:$N$7440,3,FALSE) -> 35000 | I16: =+VLOOKUP(D16,Tiempos!$A$1:$N$7440,5,FALSE) -> 12 | J16: =+VLOOKUP(D16,Tiempos!$A$1:$N$7440,7,FALSE) -> ENS03 | K16: =IF(VLOOKUP(C16,OP!$A$1:$P$27848,4,FALSE)="Cerrado",VLOOKUP(C16,OP!$A$1:$P$27848,10,FALSE),VLOOKUP(C16,OP!$A$1:$P$27848,9,FALSE)) -> 50000 | L16: =IF( IFERROR(VLOOKUP(D16,BD_Spec!$A$1:$D$2300,4,FALSE),"")="Producto Terminado", "TERMINADO", IFERROR(_xlfn.XLOOKUP(Ordenes_Mes[[#This Row],[Maquina]],Tiempos!$G$1:$G$766,Tiempos!$O$1:$O$766),"") ) -> TERMINADO | M16: =IF(OR(Ordenes_Mes[[#This Row],[Proceso]]="Plástico_lima",Ordenes_Mes[[#This Row],[Proceso]]="soplado"),24,12) -> 12 | N16: =+VLOOKUP(D16,BD_Spec!$A$1:$K$2336,7,FALSE) -> Línea_036 | O16: =+VLOOKUP(D16,BD_Spec!$A$1:$K$2336,8,FALSE) -> N/A | P16: =+VLOOKUP(C16,OP!$A$1:$P$27848,4,FALSE) -> CERRADO | Q16: =+VLOOKUP(C16,OP!$A$1:$P$27848,10,FALSE) -> 50000 | R16: =+Ordenes_Mes[[#This Row],[Fecha Inicio]] -> 46139
A17: =+MONTH(Ordenes_Mes[[#This Row],[Fecha_Conta]]) -> 4 | B17: =+VLOOKUP(C17,OP!$A$1:$P$27848,12,FALSE) -> 46125 | C17: 4009 | D17: 2310340006 | E17: Punta Carga 036F + Adaptador | F17: 1 | G17: 46127 | H17: =+VLOOKUP(D17,Tiempos!$A$1:$N$7440,3,FALSE) -> 30000 | I17: =+VLOOKUP(D17,Tiempos!$A$1:$N$7440,5,FALSE) -> 12 | J17: =+VLOOKUP(D17,Tiempos!$A$1:$N$7440,7,FALSE) -> ENS05 | K17: =IF(VLOOKUP(C17,OP!$A$1:$P$27848,4,FALSE)="Cerrado",VLOOKUP(C17,OP!$A$1:$P$27848,10,FALSE),VLOOKUP(C17,OP!$A$1:$P$27848,9,FALSE)) -> 500550 | L17: =IF( IFERROR(VLOOKUP(D17,BD_Spec!$A$1:$D$2300,4,FALSE),"")="Producto Terminado", "TERMINADO", IFERROR(_xlfn.XLOOKUP(Ordenes_Mes[[#This Row],[Maquina]],Tiempos!$G$1:$G$766,Tiempos!$O$1:$O$766),"") ) -> ENSAMBLE_LIMA | M17: =IF(OR(Ordenes_Mes[[#This Row],[Proceso]]="Plástico_lima",Ordenes_Mes[[#This Row],[Proceso]]="soplado"),24,12) -> 12 | N17: =+VLOOKUP(D17,BD_Spec!$A$1:$K$2336,7,FALSE) -> Línea_036 | O17: =+VLOOKUP(D17,BD_Spec!$A$1:$K$2336,8,FALSE) -> Colores | P17: =+VLOOKUP(C17,OP!$A$1:$P$27848,4,FALSE) -> CERRADO | Q17: =+VLOOKUP(C17,OP!$A$1:$P$27848,10,FALSE) -> 500550 | R17: =+Ordenes_Mes[[#This Row],[Fecha Inicio]] -> 46127
A18: =+MONTH(Ordenes_Mes[[#This Row],[Fecha_Conta]]) -> 4 | B18: =+VLOOKUP(C18,OP!$A$1:$P$27848,12,FALSE) -> 46121 | C18: 3986 | D18: 2310360001 | E18: Tubito Para Bolígrafo 036 | F18: 1 | G18: 46120 | H18: =+VLOOKUP(D18,Tiempos!$A$1:$N$7440,3,FALSE) -> 50000 | I18: =+VLOOKUP(D18,Tiempos!$A$1:$N$7440,5,FALSE) -> 12 | J18: =+VLOOKUP(D18,Tiempos!$A$1:$N$7440,7,FALSE) -> EXT01 | K18: 830000 | L18: =IF( IFERROR(VLOOKUP(D18,BD_Spec!$A$1:$D$2300,4,FALSE),"")="Producto Terminado", "TERMINADO", IFERROR(_xlfn.XLOOKUP(Ordenes_Mes[[#This Row],[Maquina]],Tiempos!$G$1:$G$766,Tiempos!$O$1:$O$766),"") ) -> ENSAMBLE_LIMA | M18: =IF(OR(Ordenes_Mes[[#This Row],[Proceso]]="Plástico_lima",Ordenes_Mes[[#This Row],[Proceso]]="soplado"),24,12) -> 12 | N18: =+VLOOKUP(D18,BD_Spec!$A$1:$K$2336,7,FALSE) -> Línea_036 | O18: =+VLOOKUP(D18,BD_Spec!$A$1:$K$2336,8,FALSE) -> Tubo | P18: =+VLOOKUP(C18,OP!$A$1:$P$27848,4,FALSE) -> CERRADO | Q18: =+VLOOKUP(C18,OP!$A$1:$P$27848,10,FALSE) -> 754833 | R18: =+Ordenes_Mes[[#This Row],[Fecha Inicio]] -> 46120
A19: =+MONTH(Ordenes_Mes[[#This Row],[Fecha_Conta]]) -> 4 | B19: =+VLOOKUP(C19,OP!$A$1:$P$27848,12,FALSE) -> 46118 | C19: 3925 | D19: 2310040362 | E19: Formado Crayón Triangular Jumbo LYC Amarillo | F19: =+_xlfn.XLOOKUP(D19,BD_Spec!$A$1:$A$2336,BD_Spec!$L$1:$L$2336) -> 1 | G19: 46118 | H19: =+VLOOKUP(D19,Tiempos!$A$1:$N$7440,3,FALSE) -> 25000 | I19: =+VLOOKUP(D19,Tiempos!$A$1:$N$7440,5,FALSE) -> 12 | J19: =+VLOOKUP(D19,Tiempos!$A$1:$N$7440,7,FALSE) -> FORM01 | K19: =IF(VLOOKUP(C19,OP!$A$1:$P$27848,4,FALSE)="Cerrado",VLOOKUP(C19,OP!$A$1:$P$27848,10,FALSE),VLOOKUP(C19,OP!$A$1:$P$27848,9,FALSE)) -> 6401 | L19: =IF( IFERROR(VLOOKUP(D19,BD_Spec!$A$1:$D$2300,4,FALSE),"")="Producto Terminado", "TERMINADO", IFERROR(_xlfn.XLOOKUP(Ordenes_Mes[[#This Row],[Maquina]],Tiempos!$G$1:$G$766,Tiempos!$O$1:$O$766),"") ) -> MASAS_TINTAS_LIMA | M19: =IF(OR(Ordenes_Mes[[#This Row],[Proceso]]="Plástico_lima",Ordenes_Mes[[#This Row],[Proceso]]="soplado"),24,12) -> 12 | N19: =+VLOOKUP(D19,BD_Spec!$A$1:$K$2336,7,FALSE) -> Línea_Crayón | O19: =+VLOOKUP(D19,BD_Spec!$A$1:$K$2336,8,FALSE) -> Crayón_Triángular | P19: =+VLOOKUP(C19,OP!$A$1:$P$27848,4,FALSE) -> CERRADO | Q19: =+VLOOKUP(C19,OP!$A$1:$P$27848,10,FALSE) -> 6401 | R19: =+Ordenes_Mes[[#This Row],[Fecha Inicio]] -> 46118
A20: =+MONTH(Ordenes_Mes[[#This Row],[Fecha_Conta]]) -> 4 | B20: =+VLOOKUP(C20,OP!$A$1:$P$27848,12,FALSE) -> 46118 | C20: 3926 | D20: 2310040364 | E20: Formado Crayón Triangular Jumbo LYC Anaranjado | F20: =+_xlfn.XLOOKUP(D20,BD_Spec!$A$1:$A$2336,BD_Spec!$L$1:$L$2336) -> 2 | G20: 46118 | H20: =+VLOOKUP(D20,Tiempos!$A$1:$N$7440,3,FALSE) -> 25000 | I20: =+VLOOKUP(D20,Tiempos!$A$1:$N$7440,5,FALSE) -> 12 | J20: =+VLOOKUP(D20,Tiempos!$A$1:$N$7440,7,FALSE) -> FORM01 | K20: =IF(VLOOKUP(C20,OP!$A$1:$P$27848,4,FALSE)="Cerrado",VLOOKUP(C20,OP!$A$1:$P$27848,10,FALSE),VLOOKUP(C20,OP!$A$1:$P$27848,9,FALSE)) -> 5972 | L20: =IF( IFERROR(VLOOKUP(D20,BD_Spec!$A$1:$D$2300,4,FALSE),"")="Producto Terminado", "TERMINADO", IFERROR(_xlfn.XLOOKUP(Ordenes_Mes[[#This Row],[Maquina]],Tiempos!$G$1:$G$766,Tiempos!$O$1:$O$766),"") ) -> MASAS_TINTAS_LIMA | M20: =IF(OR(Ordenes_Mes[[#This Row],[Proceso]]="Plástico_lima",Ordenes_Mes[[#This Row],[Proceso]]="soplado"),24,12) -> 12 | N20: =+VLOOKUP(D20,BD_Spec!$A$1:$K$2336,7,FALSE) -> Línea_Crayón | O20: =+VLOOKUP(D20,BD_Spec!$A$1:$K$2336,8,FALSE) -> Crayón_Triángular | P20: =+VLOOKUP(C20,OP!$A$1:$P$27848,4,FALSE) -> CERRADO | Q20: =+VLOOKUP(C20,OP!$A$1:$P$27848,10,FALSE) -> 5972 | R20: =+Ordenes_Mes[[#This Row],[Fecha Inicio]] -> 46118
A21: =+MONTH(Ordenes_Mes[[#This Row],[Fecha_Conta]]) -> 4 | B21: =+VLOOKUP(C21,OP!$A$1:$P$27848,12,FALSE) -> 46118 | C21: 3933 | D21: 2310040371 | E21: Formado Crayón Triangular Jumbo LYC Rosado | F21: =+_xlfn.XLOOKUP(D21,BD_Spec!$A$1:$A$2336,BD_Spec!$L$1:$L$2336) -> 3 | G21: 46118 | H21: =+VLOOKUP(D21,Tiempos!$A$1:$N$7440,3,FALSE) -> 25000 | I21: =+VLOOKUP(D21,Tiempos!$A$1:$N$7440,5,FALSE) -> 12 | J21: =+VLOOKUP(D21,Tiempos!$A$1:$N$7440,7,FALSE) -> FORM01 | K21: =IF(VLOOKUP(C21,OP!$A$1:$P$27848,4,FALSE)="Cerrado",VLOOKUP(C21,OP!$A$1:$P$27848,10,FALSE),VLOOKUP(C21,OP!$A$1:$P$27848,9,FALSE)) -> 6066 | L21: =IF( IFERROR(VLOOKUP(D21,BD_Spec!$A$1:$D$2300,4,FALSE),"")="Producto Terminado", "TERMINADO", IFERROR(_xlfn.XLOOKUP(Ordenes_Mes[[#This Row],[Maquina]],Tiempos!$G$1:$G$766,Tiempos!$O$1:$O$766),"") ) -> MASAS_TINTAS_LIMA | M21: =IF(OR(Ordenes_Mes[[#This Row],[Proceso]]="Plástico_lima",Ordenes_Mes[[#This Row],[Proceso]]="soplado"),24,12) -> 12 | N21: =+VLOOKUP(D21,BD_Spec!$A$1:$K$2336,7,FALSE) -> Línea_Crayón | O21: =+VLOOKUP(D21,BD_Spec!$A$1:$K$2336,8,FALSE) -> Crayón_Triángular | P21: =+VLOOKUP(C21,OP!$A$1:$P$27848,4,FALSE) -> CERRADO | Q21: =+VLOOKUP(C21,OP!$A$1:$P$27848,10,FALSE) -> 6066 | R21: =+Ordenes_Mes[[#This Row],[Fecha Inicio]] -> 46118
A22: =+MONTH(Ordenes_Mes[[#This Row],[Fecha_Conta]]) -> 4 | B22: =+VLOOKUP(C22,OP!$A$1:$P$27848,12,FALSE) -> 46118 | C22: 3924 | D22: 2310040361 | E22: Formado Crayón Triangular Jumbo LYC Rojo | F22: =+_xlfn.XLOOKUP(D22,BD_Spec!$A$1:$A$2336,BD_Spec!$L$1:$L$2336) -> 4 | G22: 46118 | H22: =+VLOOKUP(D22,Tiempos!$A$1:$N$7440,3,FALSE) -> 25000 | I22: =+VLOOKUP(D22,Tiempos!$A$1:$N$7440,5,FALSE) -> 12 | J22: =+VLOOKUP(D22,Tiempos!$A$1:$N$7440,7,FALSE) -> FORM01 | K22: =IF(VLOOKUP(C22,OP!$A$1:$P$27848,4,FALSE)="Cerrado",VLOOKUP(C22,OP!$A$1:$P$27848,10,FALSE),VLOOKUP(C22,OP!$A$1:$P$27848,9,FALSE)) -> 5988 | L22: =IF( IFERROR(VLOOKUP(D22,BD_Spec!$A$1:$D$2300,4,FALSE),"")="Producto Terminado", "TERMINADO", IFERROR(_xlfn.XLOOKUP(Ordenes_Mes[[#This Row],[Maquina]],Tiempos!$G$1:$G$766,Tiempos!$O$1:$O$766),"") ) -> MASAS_TINTAS_LIMA | M22: =IF(OR(Ordenes_Mes[[#This Row],[Proceso]]="Plástico_lima",Ordenes_Mes[[#This Row],[Proceso]]="soplado"),24,12) -> 12 | N22: =+VLOOKUP(D22,BD_Spec!$A$1:$K$2336,7,FALSE) -> Línea_Crayón | O22: =+VLOOKUP(D22,BD_Spec!$A$1:$K$2336,8,FALSE) -> Crayón_Triángular | P22: =+VLOOKUP(C22,OP!$A$1:$P$27848,4,FALSE) -> CERRADO | Q22: =+VLOOKUP(C22,OP!$A$1:$P$27848,10,FALSE) -> 5988 | R22: =+Ordenes_Mes[[#This Row],[Fecha Inicio]] -> 46118
A23: =+MONTH(Ordenes_Mes[[#This Row],[Fecha_Conta]]) -> 4 | B23: =+VLOOKUP(C23,OP!$A$1:$P$27848,12,FALSE) -> 46118 | C23: 3927 | D23: 2310040365 | E23: Formado Crayón Triangular Jumbo LYC Verde Claro | F23: =+_xlfn.XLOOKUP(D23,BD_Spec!$A$1:$A$2336,BD_Spec!$L$1:$L$2336) -> 5 | G23: 46118 | H23: =+VLOOKUP(D23,Tiempos!$A$1:$N$7440,3,FALSE) -> 25000 | I23: =+VLOOKUP(D23,Tiempos!$A$1:$N$7440,5,FALSE) -> 12 | J23: =+VLOOKUP(D23,Tiempos!$A$1:$N$7440,7,FALSE) -> FORM01 | K23: =IF(VLOOKUP(C23,OP!$A$1:$P$27848,4,FALSE)="Cerrado",VLOOKUP(C23,OP!$A$1:$P$27848,10,FALSE),VLOOKUP(C23,OP!$A$1:$P$27848,9,FALSE)) -> 5838 | L23: =IF( IFERROR(VLOOKUP(D23,BD_Spec!$A$1:$D$2300,4,FALSE),"")="Producto Terminado", "TERMINADO", IFERROR(_xlfn.XLOOKUP(Ordenes_Mes[[#This Row],[Maquina]],Tiempos!$G$1:$G$766,Tiempos!$O$1:$O$766),"") ) -> MASAS_TINTAS_LIMA | M23: =IF(OR(Ordenes_Mes[[#This Row],[Proceso]]="Plástico_lima",Ordenes_Mes[[#This Row],[Proceso]]="soplado"),24,12) -> 12 | N23: =+VLOOKUP(D23,BD_Spec!$A$1:$K$2336,7,FALSE) -> Línea_Crayón | O23: =+VLOOKUP(D23,BD_Spec!$A$1:$K$2336,8,FALSE) -> Crayón_Triángular | P23: =+VLOOKUP(C23,OP!$A$1:$P$27848,4,FALSE) -> CERRADO | Q23: =+VLOOKUP(C23,OP!$A$1:$P$27848,10,FALSE) -> 5838 | R23: =+Ordenes_Mes[[#This Row],[Fecha Inicio]] -> 46118
A24: =+MONTH(Ordenes_Mes[[#This Row],[Fecha_Conta]]) -> 4 | B24: =+VLOOKUP(C24,OP!$A$1:$P$27848,12,FALSE) -> 46118 | C24: 3928 | D24: 2310040366 | E24: Formado Crayón Triangular Jumbo LYC Verde Oscuro | F24: =+_xlfn.XLOOKUP(D24,BD_Spec!$A$1:$A$2336,BD_Spec!$L$1:$L$2336) -> 6 | G24: 46118 | H24: =+VLOOKUP(D24,Tiempos!$A$1:$N$7440,3,FALSE) -> 25000 | I24: =+VLOOKUP(D24,Tiempos!$A$1:$N$7440,5,FALSE) -> 12 | J24: =+VLOOKUP(D24,Tiempos!$A$1:$N$7440,7,FALSE) -> FORM01 | K24: =IF(VLOOKUP(C24,OP!$A$1:$P$27848,4,FALSE)="Cerrado",VLOOKUP(C24,OP!$A$1:$P$27848,10,FALSE),VLOOKUP(C24,OP!$A$1:$P$27848,9,FALSE)) -> 6451 | L24: =IF( IFERROR(VLOOKUP(D24,BD_Spec!$A$1:$D$2300,4,FALSE),"")="Producto Terminado", "TERMINADO", IFERROR(_xlfn.XLOOKUP(Ordenes_Mes[[#This Row],[Maquina]],Tiempos!$G$1:$G$766,Tiempos!$O$1:$O$766),"") ) -> MASAS_TINTAS_LIMA | M24: =IF(OR(Ordenes_Mes[[#This Row],[Proceso]]="Plástico_lima",Ordenes_Mes[[#This Row],[Proceso]]="soplado"),24,12) -> 12 | N24: =+VLOOKUP(D24,BD_Spec!$A$1:$K$2336,7,FALSE) -> Línea_Crayón | O24: =+VLOOKUP(D24,BD_Spec!$A$1:$K$2336,8,FALSE) -> Crayón_Triángular | P24: =+VLOOKUP(C24,OP!$A$1:$P$27848,4,FALSE) -> CERRADO | Q24: =+VLOOKUP(C24,OP!$A$1:$P$27848,10,FALSE) -> 6451 | R24: =+Ordenes_Mes[[#This Row],[Fecha Inicio]] -> 46118
A25: =+MONTH(Ordenes_Mes[[#This Row],[Fecha_Conta]]) -> 4 | B25: =+VLOOKUP(C25,OP!$A$1:$P$27848,12,FALSE) -> 46118 | C25: 3930 | D25: 2310040368 | E25: Formado Crayón Triangular Jumbo LYC Azul | F25: =+_xlfn.XLOOKUP(D25,BD_Spec!$A$1:$A$2336,BD_Spec!$L$1:$L$2336) -> 7 | G25: 46118 | H25: =+VLOOKUP(D25,Tiempos!$A$1:$N$7440,3,FALSE) -> 25000 | I25: =+VLOOKUP(D25,Tiempos!$A$1:$N$7440,5,FALSE) -> 12 | J25: =+VLOOKUP(D25,Tiempos!$A$1:$N$7440,7,FALSE) -> FORM01 | K25: =IF(VLOOKUP(C25,OP!$A$1:$P$27848,4,FALSE)="Cerrado",VLOOKUP(C25,OP!$A$1:$P$27848,10,FALSE),VLOOKUP(C25,OP!$A$1:$P$27848,9,FALSE)) -> 6026 | L25: =IF( IFERROR(VLOOKUP(D25,BD_Spec!$A$1:$D$2300,4,FALSE),"")="Producto Terminado", "TERMINADO", IFERROR(_xlfn.XLOOKUP(Ordenes_Mes[[#This Row],[Maquina]],Tiempos!$G$1:$G$766,Tiempos!$O$1:$O$766),"") ) -> MASAS_TINTAS_LIMA | M25: =IF(OR(Ordenes_Mes[[#This Row],[Proceso]]="Plástico_lima",Ordenes_Mes[[#This Row],[Proceso]]="soplado"),24,12) -> 12 | N25: =+VLOOKUP(D25,BD_Spec!$A$1:$K$2336,7,FALSE) -> Línea_Crayón | O25: =+VLOOKUP(D25,BD_Spec!$A$1:$K$2336,8,FALSE) -> Crayón_Triángular | P25: =+VLOOKUP(C25,OP!$A$1:$P$27848,4,FALSE) -> CERRADO | Q25: =+VLOOKUP(C25,OP!$A$1:$P$27848,10,FALSE) -> 6026 | R25: =+Ordenes_Mes[[#This Row],[Fecha Inicio]] -> 46118
A26: =+MONTH(Ordenes_Mes[[#This Row],[Fecha_Conta]]) -> 4 | B26: =+VLOOKUP(C26,OP!$A$1:$P$27848,12,FALSE) -> 46118 | C26: 3929 | D26: 2310040367 | E26: Formado Crayón Triangular Jumbo LYC Celeste | F26: =+_xlfn.XLOOKUP(D26,BD_Spec!$A$1:$A$2336,BD_Spec!$L$1:$L$2336) -> 8 | G26: 46118 | H26: =+VLOOKUP(D26,Tiempos!$A$1:$N$7440,3,FALSE) -> 25000 | I26: =+VLOOKUP(D26,Tiempos!$A$1:$N$7440,5,FALSE) -> 12 | J26: =+VLOOKUP(D26,Tiempos!$A$1:$N$7440,7,FALSE) -> FORM01 | K26: =IF(VLOOKUP(C26,OP!$A$1:$P$27848,4,FALSE)="Cerrado",VLOOKUP(C26,OP!$A$1:$P$27848,10,FALSE),VLOOKUP(C26,OP!$A$1:$P$27848,9,FALSE)) -> 5941 | L26: =IF( IFERROR(VLOOKUP(D26,BD_Spec!$A$1:$D$2300,4,FALSE),"")="Producto Terminado", "TERMINADO", IFERROR(_xlfn.XLOOKUP(Ordenes_Mes[[#This Row],[Maquina]],Tiempos!$G$1:$G$766,Tiempos!$O$1:$O$766),"") ) -> MASAS_TINTAS_LIMA | M26: =IF(OR(Ordenes_Mes[[#This Row],[Proceso]]="Plástico_lima",Ordenes_Mes[[#This Row],[Proceso]]="soplado"),24,12) -> 12 | N26: =+VLOOKUP(D26,BD_Spec!$A$1:$K$2336,7,FALSE) -> Línea_Crayón | O26: =+VLOOKUP(D26,BD_Spec!$A$1:$K$2336,8,FALSE) -> Crayón_Triángular | P26: =+VLOOKUP(C26,OP!$A$1:$P$27848,4,FALSE) -> CERRADO | Q26: =+VLOOKUP(C26,OP!$A$1:$P$27848,10,FALSE) -> 5941 | R26: =+Ordenes_Mes[[#This Row],[Fecha Inicio]] -> 46118
A27: =+MONTH(Ordenes_Mes[[#This Row],[Fecha_Conta]]) -> 4 | B27: =+VLOOKUP(C27,OP!$A$1:$P$27848,12,FALSE) -> 46118 | C27: 3935 | D27: 2310040571 | E27: Formado Crayón Triangular Jumbo LYC Blanco | F27: =+_xlfn.XLOOKUP(D27,BD_Spec!$A$1:$A$2336,BD_Spec!$L$1:$L$2336) -> 9 | G27: 46118 | H27: =+VLOOKUP(D27,Tiempos!$A$1:$N$7440,3,FALSE) -> 25000 | I27: =+VLOOKUP(D27,Tiempos!$A$1:$N$7440,5,FALSE) -> 12 | J27: =+VLOOKUP(D27,Tiempos!$A$1:$N$7440,7,FALSE) -> FORM01 | K27: =IF(VLOOKUP(C27,OP!$A$1:$P$27848,4,FALSE)="Cerrado",VLOOKUP(C27,OP!$A$1:$P$27848,10,FALSE),VLOOKUP(C27,OP!$A$1:$P$27848,9,FALSE)) -> 5811 | L27: =IF( IFERROR(VLOOKUP(D27,BD_Spec!$A$1:$D$2300,4,FALSE),"")="Producto Terminado", "TERMINADO", IFERROR(_xlfn.XLOOKUP(Ordenes_Mes[[#This Row],[Maquina]],Tiempos!$G$1:$G$766,Tiempos!$O$1:$O$766),"") ) -> MASAS_TINTAS_LIMA | M27: =IF(OR(Ordenes_Mes[[#This Row],[Proceso]]="Plástico_lima",Ordenes_Mes[[#This Row],[Proceso]]="soplado"),24,12) -> 12 | N27: =+VLOOKUP(D27,BD_Spec!$A$1:$K$2336,7,FALSE) -> Línea_Crayón | O27: =+VLOOKUP(D27,BD_Spec!$A$1:$K$2336,8,FALSE) -> Crayón_Triángular | P27: =+VLOOKUP(C27,OP!$A$1:$P$27848,4,FALSE) -> CERRADO | Q27: =+VLOOKUP(C27,OP!$A$1:$P$27848,10,FALSE) -> 5811 | R27: =+Ordenes_Mes[[#This Row],[Fecha Inicio]] -> 46118
A28: =+MONTH(Ordenes_Mes[[#This Row],[Fecha_Conta]]) -> 4 | B28: =+VLOOKUP(C28,OP!$A$1:$P$27848,12,FALSE) -> 46118 | C28: 3931 | D28: 2310040369 | E28: Formado Crayón Triangular Jumbo LYC Violeta | F28: =+_xlfn.XLOOKUP(D28,BD_Spec!$A$1:$A$2336,BD_Spec!$L$1:$L$2336) -> 10 | G28: 46118 | H28: =+VLOOKUP(D28,Tiempos!$A$1:$N$7440,3,FALSE) -> 25000 | I28: =+VLOOKUP(D28,Tiempos!$A$1:$N$7440,5,FALSE) -> 12 | J28: =+VLOOKUP(D28,Tiempos!$A$1:$N$7440,7,FALSE) -> FORM01 | K28: =IF(VLOOKUP(C28,OP!$A$1:$P$27848,4,FALSE)="Cerrado",VLOOKUP(C28,OP!$A$1:$P$27848,10,FALSE),VLOOKUP(C28,OP!$A$1:$P$27848,9,FALSE)) -> 5923 | L28: =IF( IFERROR(VLOOKUP(D28,BD_Spec!$A$1:$D$2300,4,FALSE),"")="Producto Terminado", "TERMINADO", IFERROR(_xlfn.XLOOKUP(Ordenes_Mes[[#This Row],[Maquina]],Tiempos!$G$1:$G$766,Tiempos!$O$1:$O$766),"") ) -> MASAS_TINTAS_LIMA | M28: =IF(OR(Ordenes_Mes[[#This Row],[Proceso]]="Plástico_lima",Ordenes_Mes[[#This Row],[Proceso]]="soplado"),24,12) -> 12 | N28: =+VLOOKUP(D28,BD_Spec!$A$1:$K$2336,7,FALSE) -> Línea_Crayón | O28: =+VLOOKUP(D28,BD_Spec!$A$1:$K$2336,8,FALSE) -> Crayón_Triángular | P28: =+VLOOKUP(C28,OP!$A$1:$P$27848,4,FALSE) -> CERRADO | Q28: =+VLOOKUP(C28,OP!$A$1:$P$27848,10,FALSE) -> 5923 | R28: =+Ordenes_Mes[[#This Row],[Fecha Inicio]] -> 46118
A29: =+MONTH(Ordenes_Mes[[#This Row],[Fecha_Conta]]) -> 4 | B29: =+VLOOKUP(C29,OP!$A$1:$P$27848,12,FALSE) -> 46118 | C29: 3934 | D29: 2310040372 | E29: Formado Crayón Triangular Jumbo LYC Marrón | F29: =+_xlfn.XLOOKUP(D29,BD_Spec!$A$1:$A$2336,BD_Spec!$L$1:$L$2336) -> 11 | G29: 46118 | H29: =+VLOOKUP(D29,Tiempos!$A$1:$N$7440,3,FALSE) -> 25000 | I29: =+VLOOKUP(D29,Tiempos!$A$1:$N$7440,5,FALSE) -> 12 | J29: =+VLOOKUP(D29,Tiempos!$A$1:$N$7440,7,FALSE) -> FORM01 | K29: =IF(VLOOKUP(C29,OP!$A$1:$P$27848,4,FALSE)="Cerrado",VLOOKUP(C29,OP!$A$1:$P$27848,10,FALSE),VLOOKUP(C29,OP!$A$1:$P$27848,9,FALSE)) -> 6447 | L29: =IF( IFERROR(VLOOKUP(D29,BD_Spec!$A$1:$D$2300,4,FALSE),"")="Producto Terminado", "TERMINADO", IFERROR(_xlfn.XLOOKUP(Ordenes_Mes[[#This Row],[Maquina]],Tiempos!$G$1:$G$766,Tiempos!$O$1:$O$766),"") ) -> MASAS_TINTAS_LIMA | M29: =IF(OR(Ordenes_Mes[[#This Row],[Proceso]]="Plástico_lima",Ordenes_Mes[[#This Row],[Proceso]]="soplado"),24,12) -> 12 | N29: =+VLOOKUP(D29,BD_Spec!$A$1:$K$2336,7,FALSE) -> Línea_Crayón | O29: =+VLOOKUP(D29,BD_Spec!$A$1:$K$2336,8,FALSE) -> Crayón_Triángular | P29: =+VLOOKUP(C29,OP!$A$1:$P$27848,4,FALSE) -> CERRADO | Q29: =+VLOOKUP(C29,OP!$A$1:$P$27848,10,FALSE) -> 6447 | R29: =+Ordenes_Mes[[#This Row],[Fecha Inicio]] -> 46118
A30: =+MONTH(Ordenes_Mes[[#This Row],[Fecha_Conta]]) -> 4 | B30: =+VLOOKUP(C30,OP!$A$1:$P$27848,12,FALSE) -> 46118 | C30: 3932 | D30: 2310040370 | E30: Formado Crayón Triangular Jumbo LYC Negro | F30: =+_xlfn.XLOOKUP(D30,BD_Spec!$A$1:$A$2336,BD_Spec!$L$1:$L$2336) -> 12 | G30: 46118 | H30: =+VLOOKUP(D30,Tiempos!$A$1:$N$7440,3,FALSE) -> 25000 | I30: =+VLOOKUP(D30,Tiempos!$A$1:$N$7440,5,FALSE) -> 12 | J30: =+VLOOKUP(D30,Tiempos!$A$1:$N$7440,7,FALSE) -> FORM01 | K30: =IF(VLOOKUP(C30,OP!$A$1:$P$27848,4,FALSE)="Cerrado",VLOOKUP(C30,OP!$A$1:$P$27848,10,FALSE),VLOOKUP(C30,OP!$A$1:$P$27848,9,FALSE)) -> 6424 | L30: =IF( IFERROR(VLOOKUP(D30,BD_Spec!$A$1:$D$2300,4,FALSE),"")="Producto Terminado", "TERMINADO", IFERROR(_xlfn.XLOOKUP(Ordenes_Mes[[#This Row],[Maquina]],Tiempos!$G$1:$G$766,Tiempos!$O$1:$O$766),"") ) -> MASAS_TINTAS_LIMA | M30: =IF(OR(Ordenes_Mes[[#This Row],[Proceso]]="Plástico_lima",Ordenes_Mes[[#This Row],[Proceso]]="soplado"),24,12) -> 12 | N30: =+VLOOKUP(D30,BD_Spec!$A$1:$K$2336,7,FALSE) -> Línea_Crayón | O30: =+VLOOKUP(D30,BD_Spec!$A$1:$K$2336,8,FALSE) -> Crayón_Triángular | P30: =+VLOOKUP(C30,OP!$A$1:$P$27848,4,FALSE) -> CERRADO | Q30: =+VLOOKUP(C30,OP!$A$1:$P$27848,10,FALSE) -> 6424 | R30: =+Ordenes_Mes[[#This Row],[Fecha Inicio]] -> 46118
A31: =+MONTH(Ordenes_Mes[[#This Row],[Fecha_Conta]]) -> 4 | B31: =+VLOOKUP(C31,OP!$A$1:$P$27848,12,FALSE) -> 46125 | C31: 4004 | D31: 2310030073 | E31: Masa Para Témperas Celeste LYC P.S. | F31: 1 | G31: 46127 | H31: =+VLOOKUP(D31,Tiempos!$A$1:$N$7440,3,FALSE) -> 2700 | I31: =+VLOOKUP(D31,Tiempos!$A$1:$N$7440,5,FALSE) -> 12 | J31: =+VLOOKUP(D31,Tiempos!$A$1:$N$7440,7,FALSE) -> HUBBES02 | K31: =IF(VLOOKUP(C31,OP!$A$1:$P$27848,4,FALSE)="Cerrado",VLOOKUP(C31,OP!$A$1:$P$27848,10,FALSE),VLOOKUP(C31,OP!$A$1:$P$27848,9,FALSE)) -> 600 | L31: =IF( IFERROR(VLOOKUP(D31,BD_Spec!$A$1:$D$2300,4,FALSE),"")="Producto Terminado", "TERMINADO", IFERROR(_xlfn.XLOOKUP(Ordenes_Mes[[#This Row],[Maquina]],Tiempos!$G$1:$G$766,Tiempos!$O$1:$O$766),"") ) -> MASAS_TINTAS_LIMA | M31: =IF(OR(Ordenes_Mes[[#This Row],[Proceso]]="Plástico_lima",Ordenes_Mes[[#This Row],[Proceso]]="soplado"),24,12) -> 12 | N31: =+VLOOKUP(D31,BD_Spec!$A$1:$K$2336,7,FALSE) -> Línea_30cc | O31: =+VLOOKUP(D31,BD_Spec!$A$1:$K$2336,8,FALSE) -> Colores | P31: =+VLOOKUP(C31,OP!$A$1:$P$27848,4,FALSE) -> CERRADO | Q31: =+VLOOKUP(C31,OP!$A$1:$P$27848,10,FALSE) -> 600 | R31: =+Ordenes_Mes[[#This Row],[Fecha Inicio]] -> 46127
A32: =+MONTH(Ordenes_Mes[[#This Row],[Fecha_Conta]]) -> 4 | B32: =+VLOOKUP(C32,OP!$A$1:$P$27848,12,FALSE) -> 46125 | C32: 4005 | D32: 2310030132 | E32: Masa Para Témperas Morado LYC P.S. | F32: 2 | G32: 46127 | H32: =+VLOOKUP(D32,Tiempos!$A$1:$N$7440,3,FALSE) -> 2700 | I32: =+VLOOKUP(D32,Tiempos!$A$1:$N$7440,5,FALSE) -> 12 | J32: =+VLOOKUP(D32,Tiempos!$A$1:$N$7440,7,FALSE) -> HUBBES02 | K32: =IF(VLOOKUP(C32,OP!$A$1:$P$27848,4,FALSE)="Cerrado",VLOOKUP(C32,OP!$A$1:$P$27848,10,FALSE),VLOOKUP(C32,OP!$A$1:$P$27848,9,FALSE)) -> 600 | L32: =IF( IFERROR(VLOOKUP(D32,BD_Spec!$A$1:$D$2300,4,FALSE),"")="Producto Terminado", "TERMINADO", IFERROR(_xlfn.XLOOKUP(Ordenes_Mes[[#This Row],[Maquina]],Tiempos!$G$1:$G$766,Tiempos!$O$1:$O$766),"") ) -> MASAS_TINTAS_LIMA | M32: =IF(OR(Ordenes_Mes[[#This Row],[Proceso]]="Plástico_lima",Ordenes_Mes[[#This Row],[Proceso]]="soplado"),24,12) -> 12 | N32: =+VLOOKUP(D32,BD_Spec!$A$1:$K$2336,7,FALSE) -> Línea_30cc | O32: =+VLOOKUP(D32,BD_Spec!$A$1:$K$2336,8,FALSE) -> Colores | P32: =+VLOOKUP(C32,OP!$A$1:$P$27848,4,FALSE) -> CERRADO | Q32: =+VLOOKUP(C32,OP!$A$1:$P$27848,10,FALSE) -> 600 | R32: =+Ordenes_Mes[[#This Row],[Fecha Inicio]] -> 46127
A33: =+MONTH(Ordenes_Mes[[#This Row],[Fecha_Conta]]) -> 4 | B33: =+VLOOKUP(C33,OP!$A$1:$P$27848,12,FALSE) -> 46126 | C33: 4013 | D33: 2310030021 | E33: Masa Para Témperas Marrón LYC P.S. | F33: 3 | G33: 46127 | H33: =+VLOOKUP(D33,Tiempos!$A$1:$N$7440,3,FALSE) -> 2700 | I33: =+VLOOKUP(D33,Tiempos!$A$1:$N$7440,5,FALSE) -> 12 | J33: =+VLOOKUP(D33,Tiempos!$A$1:$N$7440,7,FALSE) -> HUBBES02 | K33: =IF(VLOOKUP(C33,OP!$A$1:$P$27848,4,FALSE)="Cerrado",VLOOKUP(C33,OP!$A$1:$P$27848,10,FALSE),VLOOKUP(C33,OP!$A$1:$P$27848,9,FALSE)) -> 600 | L33: =IF( IFERROR(VLOOKUP(D33,BD_Spec!$A$1:$D$2300,4,FALSE),"")="Producto Terminado", "TERMINADO", IFERROR(_xlfn.XLOOKUP(Ordenes_Mes[[#This Row],[Maquina]],Tiempos!$G$1:$G$766,Tiempos!$O$1:$O$766),"") ) -> MASAS_TINTAS_LIMA | M33: =IF(OR(Ordenes_Mes[[#This Row],[Proceso]]="Plástico_lima",Ordenes_Mes[[#This Row],[Proceso]]="soplado"),24,12) -> 12 | N33: =+VLOOKUP(D33,BD_Spec!$A$1:$K$2336,7,FALSE) -> Línea_30cc | O33: =+VLOOKUP(D33,BD_Spec!$A$1:$K$2336,8,FALSE) -> Colores | P33: =+VLOOKUP(C33,OP!$A$1:$P$27848,4,FALSE) -> CERRADO | Q33: =+VLOOKUP(C33,OP!$A$1:$P$27848,10,FALSE) -> 600 | R33: =+Ordenes_Mes[[#This Row],[Fecha Inicio]] -> 46127
A34: =+MONTH(Ordenes_Mes[[#This Row],[Fecha_Conta]]) -> 4 | B34: =+VLOOKUP(C34,OP!$A$1:$P$27848,12,FALSE) -> 46118 | C34: 3923 | D34: 2140210005 | E34: Peine Patrullero Rojo Sin Cola 16A Lucas (NOPUCID) | F34: =+_xlfn.XLOOKUP(D34,BD_Spec!$A$1:$A$2336,BD_Spec!$L$1:$L$2336) -> 1 | G34: 46118 | H34: =+VLOOKUP(D34,Tiempos!$A$1:$N$7440,3,FALSE) -> 7000 | I34: =+VLOOKUP(D34,Tiempos!$A$1:$N$7440,5,FALSE) -> 12 | J34: =+VLOOKUP(D34,Tiempos!$A$1:$N$7440,7,FALSE) -> IMP03 | K34: =IF(VLOOKUP(C34,OP!$A$1:$P$27848,4,FALSE)="Cerrado",VLOOKUP(C34,OP!$A$1:$P$27848,10,FALSE),VLOOKUP(C34,OP!$A$1:$P$27848,9,FALSE)) -> 101232 | L34: =IF( IFERROR(VLOOKUP(D34,BD_Spec!$A$1:$D$2300,4,FALSE),"")="Producto Terminado", "TERMINADO", IFERROR(_xlfn.XLOOKUP(Ordenes_Mes[[#This Row],[Maquina]],Tiempos!$G$1:$G$766,Tiempos!$O$1:$O$766),"") ) -> TERMINADO | M34: =IF(OR(Ordenes_Mes[[#This Row],[Proceso]]="Plástico_lima",Ordenes_Mes[[#This Row],[Proceso]]="soplado"),24,12) -> 12 | N34: =+VLOOKUP(D34,BD_Spec!$A$1:$K$2336,7,FALSE) -> Línea_Peine | O34: =+VLOOKUP(D34,BD_Spec!$A$1:$K$2336,8,FALSE) -> Peine | P34: =+VLOOKUP(C34,OP!$A$1:$P$27848,4,FALSE) -> CERRADO | Q34: =+VLOOKUP(C34,OP!$A$1:$P$27848,10,FALSE) -> 101232 | R34: =+Ordenes_Mes[[#This Row],[Fecha Inicio]] -> 46118
A35: =+MONTH(Ordenes_Mes[[#This Row],[Fecha_Conta]]) -> 4 | B35: =+VLOOKUP(C35,OP!$A$1:$P$27848,12,FALSE) -> 46118 | C35: 3916 | D35: 2310230097 | E35: Frasco Para Témperas 30 cc NP P.S. | F35: =+_xlfn.XLOOKUP(D35,BD_Spec!$A$1:$A$2336,BD_Spec!$L$1:$L$2336) -> 1 | G35: 46113 | H35: =+VLOOKUP(D35,Tiempos!$A$1:$N$7440,3,FALSE) -> 44204.651 | I35: =+VLOOKUP(D35,Tiempos!$A$1:$N$7440,5,FALSE) -> 24 | J35: =+VLOOKUP(D35,Tiempos!$A$1:$N$7440,7,FALSE) -> INY02 | K35: =IF(VLOOKUP(C35,OP!$A$1:$P$27848,4,FALSE)="Cerrado",VLOOKUP(C35,OP!$A$1:$P$27848,10,FALSE),VLOOKUP(C35,OP!$A$1:$P$27848,9,FALSE)) -> 654000 | L35: =IF( IFERROR(VLOOKUP(D35,BD_Spec!$A$1:$D$2300,4,FALSE),"")="Producto Terminado", "TERMINADO", IFERROR(_xlfn.XLOOKUP(Ordenes_Mes[[#This Row],[Maquina]],Tiempos!$G$1:$G$766,Tiempos!$O$1:$O$766),"") ) -> PLÁSTICO_LIMA | M35: =IF(OR(Ordenes_Mes[[#This Row],[Proceso]]="Plástico_lima",Ordenes_Mes[[#This Row],[Proceso]]="soplado"),24,12) -> 24 | N35: =+VLOOKUP(D35,BD_Spec!$A$1:$K$2336,7,FALSE) -> Línea_30cc | O35: =+VLOOKUP(D35,BD_Spec!$A$1:$K$2336,8,FALSE) -> Frasco PLK | P35: =+VLOOKUP(C35,OP!$A$1:$P$27848,4,FALSE) -> CERRADO | Q35: =+VLOOKUP(C35,OP!$A$1:$P$27848,10,FALSE) -> 654000 | R35: =+Ordenes_Mes[[#This Row],[Fecha Inicio]] -> 46113
A36: =+MONTH(Ordenes_Mes[[#This Row],[Fecha_Conta]]) -> 4 | B36: =+VLOOKUP(C36,OP!$A$1:$P$27848,12,FALSE) -> 46118 | C36: 3870 | D36: 2310090450 | E36: Barril Para Plumón 045 - NP Piel | F36: =+_xlfn.XLOOKUP(D36,BD_Spec!$A$1:$A$2336,BD_Spec!$L$1:$L$2336) -> 1 | G36: 46118 | H36: =+VLOOKUP(D36,Tiempos!$A$1:$N$7440,3,FALSE) -> 98742.857 | I36: =+VLOOKUP(D36,Tiempos!$A$1:$N$7440,5,FALSE) -> 24 | J36: =+VLOOKUP(D36,Tiempos!$A$1:$N$7440,7,FALSE) -> INY05 | K36: =IF(VLOOKUP(C36,OP!$A$1:$P$27848,4,FALSE)="Cerrado",VLOOKUP(C36,OP!$A$1:$P$27848,10,FALSE),VLOOKUP(C36,OP!$A$1:$P$27848,9,FALSE)) -> 236000 | L36: =IF( IFERROR(VLOOKUP(D36,BD_Spec!$A$1:$D$2300,4,FALSE),"")="Producto Terminado", "TERMINADO", IFERROR(_xlfn.XLOOKUP(Ordenes_Mes[[#This Row],[Maquina]],Tiempos!$G$1:$G$766,Tiempos!$O$1:$O$766),"") ) -> PLÁSTICO_LIMA | M36: =IF(OR(Ordenes_Mes[[#This Row],[Proceso]]="Plástico_lima",Ordenes_Mes[[#This Row],[Proceso]]="soplado"),24,12) -> 24 | N36: =+VLOOKUP(D36,BD_Spec!$A$1:$K$2336,7,FALSE) -> Línea_045 | O36: =+VLOOKUP(D36,BD_Spec!$A$1:$K$2336,8,FALSE) -> Barril | P36: =+VLOOKUP(C36,OP!$A$1:$P$27848,4,FALSE) -> CERRADO | Q36: =+VLOOKUP(C36,OP!$A$1:$P$27848,10,FALSE) -> 236000 | R36: =+Ordenes_Mes[[#This Row],[Fecha Inicio]] -> 46118
A37: =+MONTH(Ordenes_Mes[[#This Row],[Fecha_Conta]]) -> 4 | B37: =+VLOOKUP(C37,OP!$A$1:$P$27848,12,FALSE) -> 46118 | C37: 3864 | D37: 2310090443 | E37: Barril Para Plumón 045 - NP Amarillo | F37: =+_xlfn.XLOOKUP(D37,BD_Spec!$A$1:$A$2336,BD_Spec!$L$1:$L$2336) -> 2 | G37: 46118 | H37: =+VLOOKUP(D37,Tiempos!$A$1:$N$7440,3,FALSE) -> 98742.857 | I37: =+VLOOKUP(D37,Tiempos!$A$1:$N$7440,5,FALSE) -> 24 | J37: =+VLOOKUP(D37,Tiempos!$A$1:$N$7440,7,FALSE) -> INY05 | K37: =IF(VLOOKUP(C37,OP!$A$1:$P$27848,4,FALSE)="Cerrado",VLOOKUP(C37,OP!$A$1:$P$27848,10,FALSE),VLOOKUP(C37,OP!$A$1:$P$27848,9,FALSE)) -> 207800 | L37: =IF( IFERROR(VLOOKUP(D37,BD_Spec!$A$1:$D$2300,4,FALSE),"")="Producto Terminado", "TERMINADO", IFERROR(_xlfn.XLOOKUP(Ordenes_Mes[[#This Row],[Maquina]],Tiempos!$G$1:$G$766,Tiempos!$O$1:$O$766),"") ) -> PLÁSTICO_LIMA | M37: =IF(OR(Ordenes_Mes[[#This Row],[Proceso]]="Plástico_lima",Ordenes_Mes[[#This Row],[Proceso]]="soplado"),24,12) -> 24 | N37: =+VLOOKUP(D37,BD_Spec!$A$1:$K$2336,7,FALSE) -> Línea_045 | O37: =+VLOOKUP(D37,BD_Spec!$A$1:$K$2336,8,FALSE) -> Barril | P37: =+VLOOKUP(C37,OP!$A$1:$P$27848,4,FALSE) -> CERRADO | Q37: =+VLOOKUP(C37,OP!$A$1:$P$27848,10,FALSE) -> 207800 | R37: =+Ordenes_Mes[[#This Row],[Fecha Inicio]] -> 46118
A38: =+MONTH(Ordenes_Mes[[#This Row],[Fecha_Conta]]) -> 4 | B38: =+VLOOKUP(C38,OP!$A$1:$P$27848,12,FALSE) -> 46118 | C38: 3869 | D38: 2310090447 | E38: Barril Para Plumón 045 - NP Anaranjado | F38: =+_xlfn.XLOOKUP(D38,BD_Spec!$A$1:$A$2336,BD_Spec!$L$1:$L$2336) -> 3 | G38: 46118 | H38: =+VLOOKUP(D38,Tiempos!$A$1:$N$7440,3,FALSE) -> 98742.857 | I38: =+VLOOKUP(D38,Tiempos!$A$1:$N$7440,5,FALSE) -> 24 | J38: =+VLOOKUP(D38,Tiempos!$A$1:$N$7440,7,FALSE) -> INY05 | K38: =IF(VLOOKUP(C38,OP!$A$1:$P$27848,4,FALSE)="Cerrado",VLOOKUP(C38,OP!$A$1:$P$27848,10,FALSE),VLOOKUP(C38,OP!$A$1:$P$27848,9,FALSE)) -> 244800 | L38: =IF( IFERROR(VLOOKUP(D38,BD_Spec!$A$1:$D$2300,4,FALSE),"")="Producto Terminado", "TERMINADO", IFERROR(_xlfn.XLOOKUP(Ordenes_Mes[[#This Row],[Maquina]],Tiempos!$G$1:$G$766,Tiempos!$O$1:$O$766),"") ) -> PLÁSTICO_LIMA | M38: =IF(OR(Ordenes_Mes[[#This Row],[Proceso]]="Plástico_lima",Ordenes_Mes[[#This Row],[Proceso]]="soplado"),24,12) -> 24 | N38: =+VLOOKUP(D38,BD_Spec!$A$1:$K$2336,7,FALSE) -> Línea_045 | O38: =+VLOOKUP(D38,BD_Spec!$A$1:$K$2336,8,FALSE) -> Barril | P38: =+VLOOKUP(C38,OP!$A$1:$P$27848,4,FALSE) -> CERRADO | Q38: =+VLOOKUP(C38,OP!$A$1:$P$27848,10,FALSE) -> 244800 | R38: =+Ordenes_Mes[[#This Row],[Fecha Inicio]] -> 46118
A39: =+MONTH(Ordenes_Mes[[#This Row],[Fecha_Conta]]) -> 4 | B39: =+VLOOKUP(C39,OP!$A$1:$P$27848,12,FALSE) -> 46118 | C39: 3867 | D39: 2310090446 | E39: Barril Para Plumón 045 - NP Rosado | F39: =+_xlfn.XLOOKUP(D39,BD_Spec!$A$1:$A$2336,BD_Spec!$L$1:$L$2336) -> 4 | G39: 46118 | H39: =+VLOOKUP(D39,Tiempos!$A$1:$N$7440,3,FALSE) -> 98742.857 | I39: =+VLOOKUP(D39,Tiempos!$A$1:$N$7440,5,FALSE) -> 24 | J39: =+VLOOKUP(D39,Tiempos!$A$1:$N$7440,7,FALSE) -> INY05 | K39: =IF(VLOOKUP(C39,OP!$A$1:$P$27848,4,FALSE)="Cerrado",VLOOKUP(C39,OP!$A$1:$P$27848,10,FALSE),VLOOKUP(C39,OP!$A$1:$P$27848,9,FALSE)) -> 246170 | L39: =IF( IFERROR(VLOOKUP(D39,BD_Spec!$A$1:$D$2300,4,FALSE),"")="Producto Terminado", "TERMINADO", IFERROR(_xlfn.XLOOKUP(Ordenes_Mes[[#This Row],[Maquina]],Tiempos!$G$1:$G$766,Tiempos!$O$1:$O$766),"") ) -> PLÁSTICO_LIMA | M39: =IF(OR(Ordenes_Mes[[#This Row],[Proceso]]="Plástico_lima",Ordenes_Mes[[#This Row],[Proceso]]="soplado"),24,12) -> 24 | N39: =+VLOOKUP(D39,BD_Spec!$A$1:$K$2336,7,FALSE) -> Línea_045 | O39: =+VLOOKUP(D39,BD_Spec!$A$1:$K$2336,8,FALSE) -> Barril | P39: =+VLOOKUP(C39,OP!$A$1:$P$27848,4,FALSE) -> CERRADO | Q39: =+VLOOKUP(C39,OP!$A$1:$P$27848,10,FALSE) -> 246170 | R39: =+Ordenes_Mes[[#This Row],[Fecha Inicio]] -> 46118
A40: =+MONTH(Ordenes_Mes[[#This Row],[Fecha_Conta]]) -> 4 | B40: =+VLOOKUP(C40,OP!$A$1:$P$27848,12,FALSE) -> 46118 | C40: 3861 | D40: 2310090440 | E40: Barril Para Plumón 045 - NP Rojo | F40: =+_xlfn.XLOOKUP(D40,BD_Spec!$A$1:$A$2336,BD_Spec!$L$1:$L$2336) -> 5 | G40: 46118 | H40: =+VLOOKUP(D40,Tiempos!$A$1:$N$7440,3,FALSE) -> 98742.857 | I40: =+VLOOKUP(D40,Tiempos!$A$1:$N$7440,5,FALSE) -> 24 | J40: =+VLOOKUP(D40,Tiempos!$A$1:$N$7440,7,FALSE) -> INY05 | K40: =IF(VLOOKUP(C40,OP!$A$1:$P$27848,4,FALSE)="Cerrado",VLOOKUP(C40,OP!$A$1:$P$27848,10,FALSE),VLOOKUP(C40,OP!$A$1:$P$27848,9,FALSE)) -> 240750 | L40: =IF( IFERROR(VLOOKUP(D40,BD_Spec!$A$1:$D$2300,4,FALSE),"")="Producto Terminado", "TERMINADO", IFERROR(_xlfn.XLOOKUP(Ordenes_Mes[[#This Row],[Maquina]],Tiempos!$G$1:$G$766,Tiempos!$O$1:$O$766),"") ) -> PLÁSTICO_LIMA | M40: =IF(OR(Ordenes_Mes[[#This Row],[Proceso]]="Plástico_lima",Ordenes_Mes[[#This Row],[Proceso]]="soplado"),24,12) -> 24 | N40: =+VLOOKUP(D40,BD_Spec!$A$1:$K$2336,7,FALSE) -> Línea_045 | O40: =+VLOOKUP(D40,BD_Spec!$A$1:$K$2336,8,FALSE) -> Barril | P40: =+VLOOKUP(C40,OP!$A$1:$P$27848,4,FALSE) -> CERRADO | Q40: =+VLOOKUP(C40,OP!$A$1:$P$27848,10,FALSE) -> 240750 | R40: =+Ordenes_Mes[[#This Row],[Fecha Inicio]] -> 46118
...

Sheet BD_Spec
A1: Código_Material | B1: Descripción_Material | C1: Línea_PT | D1: Tipo_Material | E1: Familia_PT | F1: Proceso_Interno | G1: Líneas | H1: Subcomponente | I1: Sublìnea | J1: CONTAR.SI | K1: CV | L1: Secuencia | M1: Color | N1: Peso | P1: A | Q1: A | R1: A | S1: A
A2: 2310320328 | B2: Carga Para Bolígrafo 036 PFTR Azul N | C2: Ensamble - Máquina | D2: Semiterminado | E2: N/A | F2: Carga | G2: Línea_036 | H2: Colores | I2: Carga | J2: 1 | K2: 1 | L2: 1 | M2: N/A | P2: 2310090469 | Q2: Barril Para Marcador 042 - NP Piel P.S. | R2: Piel | S2: =+VLOOKUP(R2,$V$2:$W$13,2,FALSE) -> 1 | V2: Piel | W2: 1
A3: 2310320330 | B3: Carga Para Bolígrafo 036 PFTR Negro N | C3: Ensamble - Máquina | D3: Semiterminado | E3: N/A | F3: Carga | G3: Línea_036 | H3: Colores | I3: Carga | J3: 1 | K3: 1 | L3: 1 | M3: N/A | P3: 2310090461 | Q3: Barril Para Marcador 042 - NP Amarillo P.S. | R3: Amarillo | S3: =+VLOOKUP(R3,$V$2:$W$13,2,FALSE) -> 2 | V3: Amarillo | W3: 2
A4: 2310320329 | B4: Carga Para Bolígrafo 036 PFTR Rojo N | C4: Ensamble - Máquina | D4: Semiterminado | E4: N/A | F4: Carga | G4: Línea_036 | H4: Colores | I4: Carga | J4: 1 | K4: 1 | L4: 1 | M4: N/A | P4: 2310090466 | Q4: Barril Para Marcador 042 - NP Anaranjado P.S. | R4: Anaranjado | S4: =+VLOOKUP(R4,$V$2:$W$13,2,FALSE) -> 3 | V4: Anaranjado | W4: 3
A5: 2310320348 | B5: Carga Para Bolígrafo 036 PFTR Verde N | C5: Ensamble - Máquina | D5: Semiterminado | E5: N/A | F5: Carga | G5: Línea_036 | H5: Colores | I5: Carga | J5: 1 | K5: 1 | L5: 1 | M5: N/A | P5: 2310090464 | Q5: Barril Para Marcador 042 - NP Rosado P.S. | R5: Rosado | S5: =+VLOOKUP(R5,$V$2:$W$13,2,FALSE) -> 4 | V5: Rosado | W5: 4
A6: 2110030056 | B6: Témpera Layconsa Puppy x 250 cc Blanca c/Dispensador | C6: Ensamble - Máquina | D6: Producto Terminado | E6: Témpera 250 | F6: Dosificado | G6: Línea_250cc | H6: =+BD_Spec[[#This Row],[Familia_PT]] -> Témpera 250 | I6: N/A | J6: 1 | K6: 1 | L6: 1 | M6: N/A | P6: 2310090459 | Q6: Barril Para Marcador 042 - NP Rojo P.S. | R6: Rojo | S6: =+VLOOKUP(R6,$V$2:$W$13,2,FALSE) -> 5 | V6: Rojo | W6: 5
A7: 2110030057 | B7: Témpera Layconsa Puppy x 250 cc Azul c/Dispensador | C7: Ensamble - Máquina | D7: Producto Terminado | E7: Témpera 250 | F7: Dosificado | G7: Línea_250cc | H7: =+BD_Spec[[#This Row],[Familia_PT]] -> Témpera 250 | I7: N/A | J7: 1 | K7: 1 | L7: 1 | M7: N/A | P7: 2310090465 | Q7: Barril Para Marcador 042 - NP Morado P.S. | R7: Morado | S7: =+VLOOKUP(R7,$V$2:$W$13,2,FALSE) -> 10 | V7: Morado | W7: 10
A8: 2110030058 | B8: Témpera Layconsa Puppy x 250 cc Roja c/Dispensador | C8: Ensamble - Máquina | D8: Producto Terminado | E8: Témpera 250 | F8: Dosificado | G8: Línea_250cc | H8: =+BD_Spec[[#This Row],[Familia_PT]] -> Témpera 250 | I8: N/A | J8: 1 | K8: 1 | L8: 1 | M8: N/A | P8: 2310090463 | Q8: Barril Para Marcador 042 - NP Celeste P.S. | R8: Celeste | S8: =+VLOOKUP(R8,$V$2:$W$13,2,FALSE) -> 6 | V8: Celeste | W8: 6
A9: 2110030117 | B9: Témpera Layconsa Puppy x 250 cc Morado c/Dispensador | C9: Ensamble - Máquina | D9: Producto Terminado | E9: Témpera 250 | F9: Dosificado | G9: Línea_250cc | H9: =+BD_Spec[[#This Row],[Familia_PT]] -> Témpera 250 | I9: N/A | J9: 1 | K9: 1 | L9: 1 | M9: N/A | P9: 2310090457 | Q9: Barril Para Marcador 042 - NP Azul P.S. | R9: Azul | S9: =+VLOOKUP(R9,$V$2:$W$13,2,FALSE) -> 7 | V9: Azul | W9: 7
A10: 2110030055 | B10: Témpera Layconsa Puppy x 250 cc Verde c/Dispensador | C10: Ensamble - Máquina | D10: Producto Terminado | E10: Témpera 250 | F10: Dosificado | G10: Línea_250cc | H10: =+BD_Spec[[#This Row],[Familia_PT]] -> Témpera 250 | I10: N/A | J10: 1 | K10: 1 | L10: 1 | M10: N/A | P10: 2310090468 | Q10: Barril Para Marcador 042 - NP Verde Claro P.S. | R10: Verde Claro | S10: =+VLOOKUP(R10,$V$2:$W$13,2,FALSE) -> 8 | V10: Verde Claro | W10: 8
A11: 2110030059 | B11: Témpera Layconsa Puppy x 250 cc Amarilla c/Dispensador | C11: Ensamble - Máquina | D11: Producto Terminado | E11: Témpera 250 | F11: Dosificado | G11: Línea_250cc | H11: =+BD_Spec[[#This Row],[Familia_PT]] -> Témpera 250 | I11: N/A | J11: 1 | K11: 1 | L11: 1 | M11: N/A | P11: 2310090460 | Q11: Barril Para Marcador 042 - NP Verde P.S. | R11: Verde | S11: =+VLOOKUP(R11,$V$2:$W$13,2,FALSE) -> 9 | V11: Verde | W11: 9
A12: 2110030060 | B12: Témpera Layconsa Puppy x 250 cc Piel c/Dispensador | C12: Ensamble - Máquina | D12: Producto Terminado | E12: Témpera 250 | F12: Dosificado | G12: Línea_250cc | H12: =+BD_Spec[[#This Row],[Familia_PT]] -> Témpera 250 | I12: N/A | J12: 1 | K12: 1 | L12: 1 | M12: N/A | P12: 2310090462 | Q12: Barril Para Marcador 042 - NP Marrón P.S. | R12: Marrón | S12: =+VLOOKUP(R12,$V$2:$W$13,2,FALSE) -> 11 | V12: Marrón | W12: 11
A13: 2110030078 | B13: Témpera Layconsa Puppy x 250 cc Marrón c/Dispensador | C13: Ensamble - Máquina | D13: Producto Terminado | E13: Témpera 250 | F13: Dosificado | G13: Línea_250cc | H13: =+BD_Spec[[#This Row],[Familia_PT]] -> Témpera 250 | I13: N/A | J13: 1 | K13: 1 | L13: 1 | M13: N/A | P13: 2310090458 | Q13: Barril Para Marcador 042 - NP Negro P.S. | R13: Negro | S13: =+VLOOKUP(R13,$V$2:$W$13,2,FALSE) -> 12 | V13: Negro | W13: 12
A14: 2110030081 | B14: Témpera Layconsa Puppy x 250 cc Celeste c/Dispensador | C14: Ensamble - Máquina | D14: Producto Terminado | E14: Témpera 250 | F14: Dosificado | G14: Línea_250cc | H14: =+BD_Spec[[#This Row],[Familia_PT]] -> Témpera 250 | I14: N/A | J14: 1 | K14: 1 | L14: 1 | M14: N/A | P14: 2310160355 | Q14: Tapa Para Marcador 042 - N Piel P.S. | R14: Piel | S14: =+VLOOKUP(R14,$V$2:$W$13,2,FALSE) -> 1
A15: 2110030082 | B15: Témpera Layconsa Puppy x 250 cc Anaranjado c/Dispensador | C15: Ensamble - Máquina | D15: Producto Terminado | E15: Témpera 250 | F15: Dosificado | G15: Línea_250cc | H15: =+BD_Spec[[#This Row],[Familia_PT]] -> Témpera 250 | I15: N/A | J15: 1 | K15: 1 | L15: 1 | M15: N/A | P15: 2310160242 | Q15: Tapa Para Marcador 042 - N Amarillo P.S. | R15: Amarillo | S15: =+VLOOKUP(R15,$V$2:$W$13,2,FALSE) -> 2 | V15: Blanco | W15: 9
A16: 2110030119 | B16: Témpera Layconsa Puppy x 250 cc Verde Limón c/Dispensador | C16: Ensamble - Máquina | D16: Producto Terminado | E16: Témpera 250 | F16: Dosificado | G16: Línea_250cc | H16: =+BD_Spec[[#This Row],[Familia_PT]] -> Témpera 250 | I16: N/A | J16: 1 | K16: 1 | L16: 1 | M16: N/A | P16: 2310160247 | Q16: Tapa Para Marcador 042 - N Anaranjado P.S. | R16: Anaranjado | S16: =+VLOOKUP(R16,$V$2:$W$13,2,FALSE) -> 3 | V16: Amarillo | W16: 1
A17: 2110030079 | B17: Témpera Layconsa Puppy x 250 cc Negro c/Dispensador | C17: Ensamble - Máquina | D17: Producto Terminado | E17: Témpera 250 | F17: Dosificado | G17: Línea_250cc | H17: =+BD_Spec[[#This Row],[Familia_PT]] -> Témpera 250 | I17: N/A | J17: 1 | K17: 1 | L17: 1 | M17: N/A | P17: 2310160245 | Q17: Tapa Para Marcador 042 - N Rosado P.S. | R17: Rosado | S17: =+VLOOKUP(R17,$V$2:$W$13,2,FALSE) -> 4 | V17: Anaranjado | W17: 2
A18: 2110030080 | B18: Témpera Layconsa Puppy x 250 cc Rosado c/Dispensador | C18: Ensamble - Máquina | D18: Producto Terminado | E18: Témpera 250 | F18: Dosificado | G18: Línea_250cc | H18: =+BD_Spec[[#This Row],[Familia_PT]] -> Témpera 250 | I18: N/A | J18: 1 | K18: 1 | L18: 1 | M18: N/A | P18: 2310160240 | Q18: Tapa Para Marcador 042 - N Rojo P.S. | R18: Rojo | S18: =+VLOOKUP(R18,$V$2:$W$13,2,FALSE) -> 5 | V18: Rosado | W18: 3
A19: 2110030120 | B19: Témpera Layconsa Puppy x 250 cc Neón Amarillo c/Dispensador | C19: Ensamble - Máquina | D19: Producto Terminado | E19: Témpera 250 | F19: Dosificado | G19: Línea_250cc | H19: =+BD_Spec[[#This Row],[Familia_PT]] -> Témpera 250 | I19: N/A | J19: 1 | K19: 1 | L19: 1 | M19: N/A | P19: 2310160246 | Q19: Tapa Para Marcador 042 - N Morado P.S. | R19: Morado | S19: =+VLOOKUP(R19,$V$2:$W$13,2,FALSE) -> 10 | V19: Rojo | W19: 4
A20: 2110030121 | B20: Témpera Layconsa Puppy x 250 cc Neón Violeta c/Dispensador | C20: Ensamble - Máquina | D20: Producto Terminado | E20: Témpera 250 | F20: Dosificado | G20: Línea_250cc | H20: =+BD_Spec[[#This Row],[Familia_PT]] -> Témpera 250 | I20: N/A | J20: 1 | K20: 1 | L20: 1 | M20: N/A | P20: 2310160244 | Q20: Tapa Para Marcador 042 - N Celeste P.S. | R20: Celeste | S20: =+VLOOKUP(R20,$V$2:$W$13,2,FALSE) -> 6 | V20: Morado | W20: 10
A21: 2110030123 | B21: Témpera Layconsa Puppy x 250 cc Neón Rosado c/Dispensador | C21: Ensamble - Máquina | D21: Producto Terminado | E21: Témpera 250 | F21: Dosificado | G21: Línea_250cc | H21: =+BD_Spec[[#This Row],[Familia_PT]] -> Témpera 250 | I21: N/A | J21: 1 | K21: 1 | L21: 1 | M21: N/A | P21: 2310160238 | Q21: Tapa Para Marcador 042 - N Azul P.S. | R21: Azul | S21: =+VLOOKUP(R21,$V$2:$W$13,2,FALSE) -> 7 | V21: Celeste | W21: 8
A22: 2110030124 | B22: Témpera Layconsa Puppy x 250 cc Neón Verde c/Dispensador | C22: Ensamble - Máquina | D22: Producto Terminado | E22: Témpera 250 | F22: Dosificado | G22: Línea_250cc | H22: =+BD_Spec[[#This Row],[Familia_PT]] -> Témpera 250 | I22: N/A | J22: 1 | K22: 1 | L22: 1 | M22: N/A | P22: 2310160356 | Q22: Tapa Para Marcador 042 - N Verde Claro P.S. | R22: Verde Claro | S22: =+VLOOKUP(R22,$V$2:$W$13,2,FALSE) -> 8 | V22: Azul | W22: 7
A23: 2110030118 | B23: Témpera Layconsa Puppy x 250 cc Fucsia c/Dispensador | C23: Ensamble - Máquina | D23: Producto Terminado | E23: Témpera 250 | F23: Dosificado | G23: Línea_250cc | H23: =+BD_Spec[[#This Row],[Familia_PT]] -> Témpera 250 | I23: N/A | J23: 1 | K23: 1 | L23: 1 | M23: N/A | P23: 2310160241 | Q23: Tapa Para Marcador 042 - N Verde P.S. | R23: Verde | S23: =+VLOOKUP(R23,$V$2:$W$13,2,FALSE) -> 9 | V23: Verde Claro | W23: 5
A24: 2110030122 | B24: Témpera Layconsa Puppy x 250 cc Neón Naranja c/Dispensador | C24: Ensamble - Máquina | D24: Producto Terminado | E24: Témpera 250 | F24: Dosificado | G24: Línea_250cc | H24: =+BD_Spec[[#This Row],[Familia_PT]] -> Témpera 250 | I24: N/A | J24: 1 | K24: 1 | L24: 1 | M24: N/A | P24: 2310160243 | Q24: Tapa Para Marcador 042 - N Marrón P.S. | R24: Marrón | S24: =+VLOOKUP(R24,$V$2:$W$13,2,FALSE) -> 11 | V24: Verde | W24: 6
A25: 2110030190 | B25: Témpera Layconsa Puppy x 250 cc Turquesa c/Dispensador | C25: Ensamble - Máquina | D25: Producto Terminado | E25: Témpera 250 | F25: Dosificado | G25: Línea_250cc | H25: =+BD_Spec[[#This Row],[Familia_PT]] -> Témpera 250 | I25: N/A | J25: 1 | K25: 1 | L25: 1 | M25: N/A | P25: 2310160239 | Q25: Tapa Para Marcador 042 - N Negro P.S. | R25: Negro | S25: =+VLOOKUP(R25,$V$2:$W$13,2,FALSE) -> 12 | V25: Marrón | W25: 11
A26: 2110030191 | B26: Témpera Layconsa Puppy x 250 cc Neón Rojo c/Dispensador | C26: Ensamble - Máquina | D26: Producto Terminado | E26: Témpera 250 | F26: Dosificado | G26: Línea_250cc | H26: =+BD_Spec[[#This Row],[Familia_PT]] -> Témpera 250 | I26: N/A | J26: 1 | K26: 1 | L26: 1 | M26: N/A | P26: 2310160353 | Q26: Tapita Para Marcador 042 - N Piel | R26: Piel | S26: =+VLOOKUP(R26,$V$2:$W$13,2,FALSE) -> 1 | V26: Negro | W26: 12
A27: 2110030195 | B27: Témpera Rojo Arti x 250 ML | C27: Ensamble - Máquina | D27: Producto Terminado | E27: Cola | F27: Dosificado | G27: Línea_cola | H27: N/A | I27: N/A | J27: 1 | K27: 1 | L27: 1 | M27: N/A | P27: 2310160252 | Q27: Tapita Para Marcador 042 - N Amarillo | R27: Amarillo | S27: =+VLOOKUP(R27,$V$2:$W$13,2,FALSE) -> 2
A28: 2110030236 | B28: Témpera Violeta Arti x 250 ML | C28: Ensamble - Máquina | D28: Producto Terminado | E28: Cola | F28: Dosificado | G28: Línea_cola | H28: N/A | I28: N/A | J28: 1 | K28: 1 | L28: 1 | M28: N/A | P28: 2310160257 | Q28: Tapita Para Marcador 042 - N Anaranjado | R28: Anaranjado | S28: =+VLOOKUP(R28,$V$2:$W$13,2,FALSE) -> 3
A29: 2110030237 | B29: Témpera Marrón Arti x 250 ML | C29: Ensamble - Máquina | D29: Producto Terminado | E29: Cola | F29: Dosificado | G29: Línea_cola | H29: N/A | I29: N/A | J29: 1 | K29: 1 | L29: 1 | M29: N/A | P29: 2310160255 | Q29: Tapita Para Marcador 042 - N Rosado | R29: Rosado | S29: =+VLOOKUP(R29,$V$2:$W$13,2,FALSE) -> 4
A30: 2110030239 | B30: Témpera Azul Celeste Arti x 250 ML | C30: Ensamble - Máquina | D30: Producto Terminado | E30: Cola | F30: Dosificado | G30: Línea_cola | H30: N/A | I30: N/A | J30: 1 | K30: 1 | L30: 1 | M30: N/A | P30: 2310160250 | Q30: Tapita Para Marcador 042 - N Rojo | R30: Rojo | S30: =+VLOOKUP(R30,$V$2:$W$13,2,FALSE) -> 5
